5:return {{["x"] = 0, ["y"] = 0, ["z"] = 0, ["name"] = "nodes_nature:limestone"}, {["x"] = 0, ["y"] = 0, ["z"] = 1, ["name"] = "nodes_nature:limestone"}, {["x"] = 0, ["y"] = 0, ["z"] = 2, ["name"] = "nodes_nature:limestone"}, {["x"] = 0, ["y"] = 0, ["z"] = 3, ["name"] = "nodes_nature:limestone"}, {["x"] = 0, ["y"] = 0, ["z"] = 4, ["name"] = "nodes_nature:limestone"}, {["x"] = 0, ["y"] = 0, ["z"] = 5, ["name"] = "nodes_nature:limestone"}, {["x"] = 0, ["y"] = 0, ["z"] = 6, ["name"] = "nodes_nature:limestone"}, {["x"] = 0, ["y"] = 0, ["z"] = 7, ["name"] = "nodes_nature:limestone"}, {["x"] = 0, ["y"] = 0, ["z"] = 8, ["name"] = "nodes_nature:limestone"}, {["x"] = 0, ["y"] = 0, ["z"] = 9, ["name"] = "nodes_nature:limestone"}, {["x"] = 0, ["y"] = 0, ["z"] = 10, ["name"] = "nodes_nature:limestone"}, {["x"] = 0, ["y"] = 0, ["z"] = 11, ["name"] = "nodes_nature:limestone"}, {["x"] = 0, ["y"] = 0, ["z"] = 12, ["name"] = "nodes_nature:limestone"}, {["x"] = 0, ["y"] = 0, ["z"] = 13, ["name"] = "nodes_nature:limestone"}, {["x"] = 0, ["y"] = 0, ["z"] = 14, ["name"] = "nodes_nature:limestone"}, {["x"] = 0, ["y"] = 0, ["z"] = 15, ["name"] = "nodes_nature:limestone"}, {["x"] = 0, ["y"] = 0, ["z"] = 16, ["name"] = "nodes_nature:limestone"}, {["x"] = 0, ["y"] = 0, ["z"] = 17, ["name"] = "nodes_nature:limestone"}, {["x"] = 0, ["y"] = 0, ["z"] = 18, ["name"] = "nodes_nature:limestone"}, {["x"] = 0, ["y"] = 1, ["z"] = 0, ["name"] = "nodes_nature:limestone"}, {["x"] = 0, ["y"] = 1, ["z"] = 1, ["name"] = "nodes_nature:limestone"}, {["x"] = 0, ["y"] = 1, ["z"] = 2, ["name"] = "nodes_nature:limestone"}, {["x"] = 0, ["y"] = 1, ["z"] = 3, ["name"] = "nodes_nature:limestone"}, {["x"] = 0, ["y"] = 1, ["z"] = 4, ["name"] = "nodes_nature:limestone"}, {["x"] = 0, ["y"] = 1, ["z"] = 5, ["name"] = "nodes_nature:limestone"}, {["x"] = 0, ["y"] = 1, ["z"] = 6, ["name"] = "nodes_nature:limestone"}, {["x"] = 0, ["y"] = 1, ["z"] = 7, ["name"] = "nodes_nature:limestone"}, {["x"] = 0, ["y"] = 1, ["z"] = 8, ["name"] = "nodes_nature:limestone"}, {["x"] = 0, ["y"] = 1, ["z"] = 9, ["name"] = "nodes_nature:limestone"}, {["x"] = 0, ["y"] = 1, ["z"] = 10, ["name"] = "nodes_nature:limestone"}, {["x"] = 0, ["y"] = 1, ["z"] = 11, ["name"] = "nodes_nature:limestone"}, {["x"] = 0, ["y"] = 1, ["z"] = 12, ["name"] = "nodes_nature:limestone"}, {["x"] = 0, ["y"] = 1, ["z"] = 13, ["name"] = "nodes_nature:limestone"}, {["x"] = 0, ["y"] = 1, ["z"] = 14, ["name"] = "nodes_nature:limestone"}, {["x"] = 0, ["y"] = 1, ["z"] = 15, ["name"] = "nodes_nature:limestone"}, {["x"] = 0, ["y"] = 1, ["z"] = 16, ["name"] = "nodes_nature:limestone"}, {["x"] = 0, ["y"] = 1, ["z"] = 17, ["name"] = "nodes_nature:limestone"}, {["x"] = 0, ["y"] = 1, ["z"] = 18, ["name"] = "nodes_nature:sand_wet_salty"}, {["x"] = 0, ["y"] = 2, ["z"] = 0, ["name"] = "nodes_nature:limestone"}, {["x"] = 0, ["y"] = 2, ["z"] = 1, ["name"] = "nodes_nature:limestone"}, {["x"] = 0, ["y"] = 2, ["z"] = 2, ["name"] = "nodes_nature:limestone"}, {["x"] = 0, ["y"] = 2, ["z"] = 3, ["name"] = "nodes_nature:limestone"}, {["x"] = 0, ["y"] = 2, ["z"] = 4, ["name"] = "nodes_nature:limestone"}, {["x"] = 0, ["y"] = 2, ["z"] = 5, ["name"] = "nodes_nature:limestone"}, {["x"] = 0, ["y"] = 2, ["z"] = 6, ["name"] = "nodes_nature:limestone"}, {["x"] = 0, ["y"] = 2, ["z"] = 7, ["name"] = "nodes_nature:limestone"}, {["x"] = 0, ["y"] = 2, ["z"] = 8, ["name"] = "nodes_nature:limestone"}, {["x"] = 0, ["y"] = 2, ["z"] = 9, ["name"] = "nodes_nature:limestone"}, {["x"] = 0, ["y"] = 2, ["z"] = 10, ["name"] = "nodes_nature:limestone"}, {["x"] = 0, ["y"] = 2, ["z"] = 11, ["name"] = "nodes_nature:limestone"}, {["x"] = 0, ["y"] = 2, ["z"] = 12, ["name"] = "nodes_nature:limestone"}, {["x"] = 0, ["y"] = 2, ["z"] = 13, ["name"] = "nodes_nature:limestone"}, {["x"] = 0, ["y"] = 2, ["z"] = 14, ["name"] = "nodes_nature:sand_wet_salty"}, {["x"] = 0, ["y"] = 2, ["z"] = 15, ["name"] = "nodes_nature:sand_wet_salty"}, {["x"] = 0, ["y"] = 2, ["z"] = 16, ["name"] = "nodes_nature:sand_wet_salty"}, {["x"] = 0, ["y"] = 2, ["z"] = 17, ["name"] = "nodes_nature:sand_wet_salty"}, {["x"] = 0, ["y"] = 2, ["z"] = 18, ["name"] = "nodes_nature:sand_wet_salty"}, {["x"] = 0, ["y"] = 3, ["z"] = 0, ["name"] = "nodes_nature:limestone"}, {["x"] = 0, ["y"] = 3, ["z"] = 1, ["name"] = "nodes_nature:limestone"}, {["x"] = 0, ["y"] = 3, ["z"] = 2, ["name"] = "nodes_nature:limestone"}, {["x"] = 0, ["y"] = 3, ["z"] = 3, ["name"] = "nodes_nature:limestone"}, {["x"] = 0, ["y"] = 3, ["z"] = 4, ["name"] = "nodes_nature:limestone"}, {["x"] = 0, ["y"] = 3, ["z"] = 5, ["name"] = "nodes_nature:limestone"}, {["x"] = 0, ["y"] = 3, ["z"] = 6, ["name"] = "nodes_nature:limestone"}, {["x"] = 0, ["y"] = 3, ["z"] = 7, ["name"] = "nodes_nature:limestone"}, {["x"] = 0, ["y"] = 3, ["z"] = 8, ["name"] = "nodes_nature:limestone"}, {["x"] = 0, ["y"] = 3, ["z"] = 9, ["name"] = "nodes_nature:limestone"}, {["x"] = 0, ["y"] = 3, ["z"] = 10, ["name"] = "nodes_nature:sand_wet_salty"}, {["x"] = 0, ["y"] = 3, ["z"] = 11, ["name"] = "nodes_nature:sand_wet_salty"}, {["x"] = 0, ["y"] = 3, ["z"] = 12, ["name"] = "nodes_nature:sand_wet_salty"}, {["x"] = 0, ["y"] = 3, ["z"] = 13, ["name"] = "nodes_nature:sand_wet_salty"}, {["x"] = 0, ["y"] = 3, ["z"] = 14, ["name"] = "nodes_nature:sand_wet_salty"}, {["x"] = 0, ["y"] = 3, ["z"] = 15, ["name"] = "nodes_nature:sand_wet_salty"}, {["x"] = 0, ["y"] = 3, ["z"] = 16, ["name"] = "nodes_nature:sand_wet_salty"}, {["x"] = 0, ["y"] = 3, ["z"] = 17, ["name"] = "nodes_nature:sand_wet_salty"}, {["x"] = 0, ["y"] = 3, ["z"] = 18, ["name"] = "nodes_nature:sand_wet_salty"}, {["x"] = 0, ["y"] = 4, ["z"] = 0, ["name"] = "nodes_nature:limestone"}, {["x"] = 0, ["y"] = 4, ["z"] = 1, ["name"] = "nodes_nature:limestone"}, {["x"] = 0, ["y"] = 4, ["z"] = 2, ["name"] = "nodes_nature:limestone"}, {["x"] = 0, ["y"] = 4, ["z"] = 3, ["name"] = "nodes_nature:limestone"}, {["x"] = 0, ["y"] = 4, ["z"] = 4, ["name"] = "nodes_nature:limestone"}, {["x"] = 0, ["y"] = 4, ["z"] = 5, ["name"] = "nodes_nature:limestone"}, {["x"] = 0, ["y"] = 4, ["z"] = 6, ["name"] = "nodes_nature:limestone"}, {["x"] = 0, ["y"] = 4, ["z"] = 7, ["name"] = "nodes_nature:sand_wet_salty"}, {["x"] = 0, ["y"] = 4, ["z"] = 8, ["name"] = "nodes_nature:sand_wet_salty"}, {["x"] = 0, ["y"] = 4, ["z"] = 9, ["name"] = "nodes_nature:sand_wet_salty"}, {["x"] = 0, ["y"] = 4, ["z"] = 10, ["name"] = "nodes_nature:sand_wet_salty"}, {["x"] = 0, ["y"] = 4, ["z"] = 11, ["name"] = "nodes_nature:sand_wet_salty"}, {["x"] = 0, ["y"] = 4, ["z"] = 12, ["name"] = "nodes_nature:sand_wet_salty"}, {["x"] = 0, ["y"] = 4, ["z"] = 13, ["name"] = "nodes_nature:sand_wet_salty"}, {["x"] = 0, ["y"] = 4, ["z"] = 14, ["name"] = "nodes_nature:sand_wet_salty"}, {["x"] = 0, ["y"] = 4, ["z"] = 15, ["name"] = "nodes_nature:sand_wet_salty"}, {["x"] = 0, ["param2"] = 16, ["y"] = 4, ["param1"] = 156, ["z"] = 16, ["name"] = "nodes_nature:seagrass"}, {["x"] = 0, ["param2"] = 16, ["y"] = 4, ["param1"] = 172, ["z"] = 17, ["name"] = "nodes_nature:seagrass"}, {["x"] = 0, ["y"] = 4, ["param1"] = 155, ["z"] = 18, ["name"] = "nodes_nature:salt_water_source"}, {["x"] = 0, ["y"] = 5, ["z"] = 0, ["name"] = "nodes_nature:limestone"}, {["x"] = 0, ["y"] = 5, ["z"] = 1, ["name"] = "nodes_nature:limestone"}, {["x"] = 0, ["y"] = 5, ["z"] = 2, ["name"] = "nodes_nature:limestone"}, {["x"] = 0, ["y"] = 5, ["z"] = 3, ["name"] = "nodes_nature:limestone"}, {["x"] = 0, ["y"] = 5, ["z"] = 4, ["name"] = "nodes_nature:limestone"}, {["x"] = 0, ["y"] = 5, ["z"] = 5, ["name"] = "nodes_nature:sand_wet_salty"}, {["x"] = 0, ["y"] = 5, ["z"] = 6, ["name"] = "nodes_nature:sand_wet_salty"}, {["x"] = 0, ["y"] = 5, ["z"] = 7, ["name"] = "nodes_nature:sand_wet_salty"}, {["x"] = 0, ["y"] = 5, ["z"] = 8, ["name"] = "nodes_nature:sand_wet_salty"}, {["x"] = 0, ["y"] = 5, ["z"] = 9, ["name"] = "nodes_nature:sand_wet_salty"}, {["x"] = 0, ["y"] = 5, ["z"] = 10, ["name"] = "nodes_nature:sand_wet_salty"}, {["x"] = 0, ["y"] = 5, ["z"] = 11, ["name"] = "nodes_nature:sand_wet_salty"}, {["x"] = 0, ["y"] = 5, ["z"] = 12, ["name"] = "nodes_nature:sand_wet_salty"}, {["x"] = 0, ["y"] = 5, ["z"] = 13, ["name"] = "nodes_nature:sand_wet_salty"}, {["x"] = 0, ["y"] = 5, ["param1"] = 158, ["z"] = 14, ["name"] = "nodes_nature:salt_water_source"}, {["x"] = 0, ["y"] = 5, ["param1"] = 158, ["z"] = 15, ["name"] = "nodes_nature:salt_water_source"}, {["x"] = 0, ["y"] = 5, ["param1"] = 173, ["z"] = 16, ["name"] = "nodes_nature:salt_water_source"}, {["x"] = 0, ["y"] = 5, ["param1"] = 188, ["z"] = 17, ["name"] = "nodes_nature:salt_water_source"}, {["x"] = 0, ["y"] = 5, ["param1"] = 171, ["z"] = 18, ["name"] = "nodes_nature:salt_water_source"}, {["x"] = 0, ["y"] = 6, ["z"] = 0, ["name"] = "nodes_nature:limestone"}, {["x"] = 0, ["y"] = 6, ["z"] = 1, ["name"] = "nodes_nature:limestone"}, {["x"] = 0, ["y"] = 6, ["z"] = 2, ["name"] = "nodes_nature:sand_wet_salty"}, {["x"] = 0, ["y"] = 6, ["z"] = 3, ["name"] = "nodes_nature:sand_wet_salty"}, {["x"] = 0, ["y"] = 6, ["z"] = 4, ["name"] = "nodes_nature:sand_wet_salty"}, {["x"] = 0, ["y"] = 6, ["z"] = 5, ["name"] = "nodes_nature:sand_wet_salty"}, {["x"] = 0, ["y"] = 6, ["z"] = 6, ["name"] = "nodes_nature:sand_wet_salty"}, {["x"] = 0, ["y"] = 6, ["z"] = 7, ["name"] = "nodes_nature:sand_wet_salty"}, {["x"] = 0, ["y"] = 6, ["z"] = 8, ["name"] = "nodes_nature:sand_wet_salty"}, {["x"] = 0, ["y"] = 6, ["z"] = 9, ["name"] = "nodes_nature:sand_wet_salty"}, {["x"] = 0, ["y"] = 6, ["param1"] = 174, ["z"] = 10, ["name"] = "nodes_nature:salt_water_source"}, {["x"] = 0, ["y"] = 6, ["param1"] = 158, ["z"] = 11, ["name"] = "nodes_nature:salt_water_source"}, {["x"] = 0, ["y"] = 6, ["param1"] = 174, ["z"] = 12, ["name"] = "nodes_nature:salt_water_source"}, {["x"] = 0, ["y"] = 6, ["param1"] = 190, ["z"] = 13, ["name"] = "nodes_nature:salt_water_source"}, {["x"] = 0, ["y"] = 6, ["param1"] = 174, ["z"] = 14, ["name"] = "nodes_nature:salt_water_source"}, {["x"] = 0, ["y"] = 6, ["param1"] = 158, ["z"] = 15, ["name"] = "nodes_nature:salt_water_source"}, {["x"] = 0, ["y"] = 6, ["param1"] = 157, ["z"] = 16, ["name"] = "nodes_nature:salt_water_source"}, {["x"] = 0, ["y"] = 6, ["param1"] = 172, ["z"] = 17, ["name"] = "nodes_nature:salt_water_source"}, {["x"] = 0, ["y"] = 6, ["param1"] = 155, ["z"] = 18, ["name"] = "nodes_nature:salt_water_source"}, {["x"] = 0, ["y"] = 7, ["z"] = 0, ["name"] = "nodes_nature:sand_wet_salty"}, {["x"] = 0, ["y"] = 7, ["z"] = 1, ["name"] = "nodes_nature:sand_wet_salty"}, {["x"] = 0, ["y"] = 7, ["z"] = 2, ["name"] = "nodes_nature:sand_wet_salty"}, {["x"] = 0, ["y"] = 7, ["z"] = 3, ["name"] = "nodes_nature:sand_wet_salty"}, {["x"] = 0, ["y"] = 7, ["z"] = 4, ["name"] = "nodes_nature:sand_wet_salty"}, {["x"] = 0, ["y"] = 7, ["z"] = 5, ["name"] = "nodes_nature:sand_wet_salty"}, {["x"] = 0, ["y"] = 7, ["z"] = 6, ["name"] = "nodes_nature:sand_wet_salty"}, {["x"] = 0, ["y"] = 7, ["param1"] = 174, ["z"] = 7, ["name"] = "nodes_nature:salt_water_source"}, {["x"] = 0, ["y"] = 7, ["param1"] = 190, ["z"] = 8, ["name"] = "nodes_nature:salt_water_source"}, {["x"] = 0, ["y"] = 7, ["param1"] = 206, ["z"] = 9, ["name"] = "nodes_nature:salt_water_source"}, {["x"] = 0, ["y"] = 7, ["param1"] = 190, ["z"] = 10, ["name"] = "nodes_nature:salt_water_source"}, {["x"] = 0, ["y"] = 7, ["param1"] = 174, ["z"] = 11, ["name"] = "nodes_nature:salt_water_source"}, {["x"] = 0, ["y"] = 7, ["param1"] = 190, ["z"] = 12, ["name"] = "nodes_nature:salt_water_source"}, {["x"] = 0, ["y"] = 7, ["param1"] = 206, ["z"] = 13, ["name"] = "nodes_nature:salt_water_source"}, {["x"] = 0, ["y"] = 7, ["param1"] = 190, ["z"] = 14, ["name"] = "nodes_nature:salt_water_source"}, {["x"] = 0, ["y"] = 7, ["param1"] = 174, ["z"] = 15, ["name"] = "nodes_nature:salt_water_source"}, {["x"] = 0, ["y"] = 7, ["param1"] = 157, ["z"] = 16, ["name"] = "nodes_nature:salt_water_source"}, {["x"] = 0, ["y"] = 7, ["param1"] = 156, ["z"] = 17, ["name"] = "nodes_nature:salt_water_source"}, {["x"] = 0, ["y"] = 7, ["param1"] = 139, ["z"] = 18, ["name"] = "nodes_nature:salt_water_source"}, {["x"] = 0, ["y"] = 8, ["z"] = 0, ["name"] = "nodes_nature:sand_wet_salty"}, {["x"] = 0, ["y"] = 8, ["z"] = 1, ["name"] = "nodes_nature:sand_wet_salty"}, {["x"] = 0, ["y"] = 8, ["z"] = 2, ["name"] = "nodes_nature:sand_wet_salty"}, {["x"] = 0, ["y"] = 8, ["z"] = 3, ["name"] = "nodes_nature:sand_wet_salty"}, {["x"] = 0, ["y"] = 8, ["z"] = 4, ["name"] = "nodes_nature:sand_wet_salty"}, {["x"] = 0, ["y"] = 8, ["param1"] = 190, ["z"] = 5, ["name"] = "nodes_nature:salt_water_source"}, {["x"] = 0, ["y"] = 8, ["param1"] = 206, ["z"] = 6, ["name"] = "nodes_nature:salt_water_source"}, {["x"] = 0, ["y"] = 8, ["param1"] = 190, ["z"] = 7, ["name"] = "nodes_nature:salt_water_source"}, {["x"] = 0, ["y"] = 8, ["param1"] = 206, ["z"] = 8, ["name"] = "nodes_nature:salt_water_source"}, {["x"] = 0, ["meta"] = {["fields"] = {["owner"] = "singleplayer", ["infotext"] = "Sun Stone\
Owned by singleplayer"}, ["inventory"] = {}}, ["param2"] = 2, ["y"] = 8, ["param1"] = 222, ["z"] = 9, ["name"] = "artifacts:sun_stone"}, {["x"] = 0, ["y"] = 8, ["param1"] = 206, ["z"] = 10, ["name"] = "nodes_nature:salt_water_source"}, {["x"] = 0, ["y"] = 8, ["param1"] = 190, ["z"] = 11, ["name"] = "nodes_nature:salt_water_source"}, {["x"] = 0, ["y"] = 8, ["param1"] = 206, ["z"] = 12, ["name"] = "nodes_nature:salt_water_source"}, {["x"] = 0, ["meta"] = {["fields"] = {["owner"] = "singleplayer", ["infotext"] = "Sun Stone\
Owned by singleplayer"}, ["inventory"] = {}}, ["param2"] = 2, ["y"] = 8, ["param1"] = 222, ["z"] = 13, ["name"] = "artifacts:sun_stone"}, {["x"] = 0, ["y"] = 8, ["param1"] = 206, ["z"] = 14, ["name"] = "nodes_nature:salt_water_source"}, {["x"] = 0, ["y"] = 8, ["param1"] = 190, ["z"] = 15, ["name"] = "nodes_nature:salt_water_source"}, {["x"] = 0, ["y"] = 8, ["param1"] = 173, ["z"] = 16, ["name"] = "nodes_nature:salt_water_source"}, {["x"] = 0, ["y"] = 8, ["param1"] = 156, ["z"] = 17, ["name"] = "nodes_nature:salt_water_source"}, {["x"] = 0, ["y"] = 8, ["param1"] = 140, ["z"] = 18, ["name"] = "nodes_nature:salt_water_source"}, {["x"] = 0, ["y"] = 9, ["z"] = 0, ["name"] = "nodes_nature:basalt"}, {["x"] = 0, ["y"] = 9, ["z"] = 1, ["name"] = "nodes_nature:basalt"}, {["x"] = 0, ["y"] = 9, ["param1"] = 158, ["z"] = 2, ["name"] = "nodes_nature:salt_water_source"}, {["x"] = 0, ["y"] = 9, ["param1"] = 174, ["z"] = 3, ["name"] = "nodes_nature:salt_water_source"}, {["x"] = 0, ["y"] = 9, ["param1"] = 190, ["z"] = 4, ["name"] = "nodes_nature:salt_water_source"}, {["x"] = 0, ["y"] = 9, ["param1"] = 206, ["z"] = 5, ["name"] = "nodes_nature:salt_water_source"}, {["x"] = 0, ["meta"] = {["fields"] = {["owner"] = "singleplayer", ["infotext"] = "Sun Stone\
Owned by singleplayer"}, ["inventory"] = {}}, ["param2"] = 2, ["y"] = 9, ["param1"] = 222, ["z"] = 6, ["name"] = "artifacts:sun_stone"}, {["x"] = 0, ["y"] = 9, ["param1"] = 206, ["z"] = 7, ["name"] = "nodes_nature:salt_water_source"}, {["x"] = 0, ["y"] = 9, ["param1"] = 190, ["z"] = 8, ["name"] = "nodes_nature:salt_water_source"}, {["x"] = 0, ["y"] = 9, ["param1"] = 206, ["z"] = 9, ["name"] = "nodes_nature:salt_water_source"}, {["x"] = 0, ["y"] = 9, ["param1"] = 190, ["z"] = 10, ["name"] = "nodes_nature:salt_water_source"}, {["x"] = 0, ["y"] = 9, ["param1"] = 174, ["z"] = 11, ["name"] = "nodes_nature:salt_water_source"}, {["x"] = 0, ["y"] = 9, ["param1"] = 190, ["z"] = 12, ["name"] = "nodes_nature:salt_water_source"}, {["x"] = 0, ["y"] = 9, ["param1"] = 206, ["z"] = 13, ["name"] = "nodes_nature:salt_water_source"}, {["x"] = 0, ["y"] = 9, ["param1"] = 190, ["z"] = 14, ["name"] = "nodes_nature:salt_water_source"}, {["x"] = 0, ["y"] = 9, ["param1"] = 174, ["z"] = 15, ["name"] = "nodes_nature:salt_water_source"}, {["x"] = 0, ["y"] = 9, ["param1"] = 157, ["z"] = 16, ["name"] = "nodes_nature:salt_water_source"}, {["x"] = 0, ["y"] = 9, ["param1"] = 141, ["z"] = 17, ["name"] = "nodes_nature:salt_water_source"}, {["x"] = 0, ["y"] = 9, ["param1"] = 125, ["z"] = 18, ["name"] = "nodes_nature:salt_water_source"}, {["x"] = 0, ["y"] = 10, ["param1"] = 174, ["z"] = 0, ["name"] = "nodes_nature:salt_water_source"}, {["x"] = 0, ["y"] = 10, ["param1"] = 190, ["z"] = 1, ["name"] = "nodes_nature:salt_water_source"}, {["x"] = 0, ["y"] = 10, ["param1"] = 174, ["z"] = 2, ["name"] = "nodes_nature:salt_water_source"}, {["x"] = 0, ["y"] = 10, ["param1"] = 158, ["z"] = 3, ["name"] = "nodes_nature:salt_water_source"}, {["x"] = 0, ["y"] = 10, ["param1"] = 174, ["z"] = 4, ["name"] = "nodes_nature:salt_water_source"}, {["x"] = 0, ["y"] = 10, ["param1"] = 190, ["z"] = 5, ["name"] = "nodes_nature:salt_water_source"}, {["x"] = 0, ["y"] = 10, ["param1"] = 206, ["z"] = 6, ["name"] = "nodes_nature:salt_water_source"}, {["x"] = 0, ["y"] = 10, ["param1"] = 190, ["z"] = 7, ["name"] = "nodes_nature:salt_water_source"}, {["x"] = 0, ["y"] = 10, ["param1"] = 174, ["z"] = 8, ["name"] = "nodes_nature:salt_water_source"}, {["x"] = 0, ["y"] = 10, ["param1"] = 190, ["z"] = 9, ["name"] = "nodes_nature:salt_water_source"}, {["x"] = 0, ["y"] = 10, ["param1"] = 174, ["z"] = 10, ["name"] = "nodes_nature:salt_water_source"}, {["x"] = 0, ["y"] = 10, ["param1"] = 158, ["z"] = 11, ["name"] = "nodes_nature:salt_water_source"}, {["x"] = 0, ["y"] = 10, ["param1"] = 174, ["z"] = 12, ["name"] = "nodes_nature:salt_water_source"}, {["x"] = 0, ["y"] = 10, ["param1"] = 190, ["z"] = 13, ["name"] = "nodes_nature:salt_water_source"}, {["x"] = 0, ["y"] = 10, ["param1"] = 174, ["z"] = 14, ["name"] = "nodes_nature:salt_water_source"}, {["x"] = 0, ["y"] = 10, ["param1"] = 158, ["z"] = 15, ["name"] = "nodes_nature:salt_water_source"}, {["x"] = 0, ["y"] = 10, ["param1"] = 174, ["z"] = 16, ["name"] = "nodes_nature:salt_water_source"}, {["x"] = 0, ["y"] = 10, ["param1"] = 158, ["z"] = 17, ["name"] = "nodes_nature:salt_water_source"}, {["x"] = 0, ["y"] = 10, ["param1"] = 142, ["z"] = 18, ["name"] = "nodes_nature:salt_water_source"}, {["x"] = 1, ["y"] = 0, ["z"] = 0, ["name"] = "nodes_nature:limestone"}, {["x"] = 1, ["y"] = 0, ["z"] = 1, ["name"] = "nodes_nature:limestone"}, {["x"] = 1, ["y"] = 0, ["z"] = 2, ["name"] = "nodes_nature:limestone"}, {["x"] = 1, ["y"] = 0, ["z"] = 3, ["name"] = "nodes_nature:limestone"}, {["x"] = 1, ["y"] = 0, ["z"] = 4, ["name"] = "nodes_nature:limestone"}, {["x"] = 1, ["y"] = 0, ["z"] = 5, ["name"] = "nodes_nature:limestone"}, {["x"] = 1, ["y"] = 0, ["z"] = 6, ["name"] = "nodes_nature:limestone"}, {["x"] = 1, ["y"] = 0, ["z"] = 7, ["name"] = "nodes_nature:limestone"}, {["x"] = 1, ["y"] = 0, ["z"] = 8, ["name"] = "nodes_nature:limestone"}, {["x"] = 1, ["y"] = 0, ["z"] = 9, ["name"] = "nodes_nature:limestone"}, {["x"] = 1, ["y"] = 0, ["z"] = 10, ["name"] = "nodes_nature:limestone"}, {["x"] = 1, ["y"] = 0, ["z"] = 11, ["name"] = "nodes_nature:limestone"}, {["x"] = 1, ["y"] = 0, ["z"] = 12, ["name"] = "nodes_nature:limestone"}, {["x"] = 1, ["y"] = 0, ["z"] = 13, ["name"] = "nodes_nature:limestone"}, {["x"] = 1, ["y"] = 0, ["z"] = 14, ["name"] = "nodes_nature:limestone"}, {["x"] = 1, ["y"] = 0, ["z"] = 15, ["name"] = "nodes_nature:limestone"}, {["x"] = 1, ["y"] = 0, ["z"] = 16, ["name"] = "nodes_nature:limestone"}, {["x"] = 1, ["y"] = 0, ["z"] = 17, ["name"] = "nodes_nature:limestone"}, {["x"] = 1, ["y"] = 0, ["z"] = 18, ["name"] = "nodes_nature:limestone"}, {["x"] = 1, ["y"] = 1, ["z"] = 0, ["name"] = "nodes_nature:limestone"}, {["x"] = 1, ["y"] = 1, ["z"] = 1, ["name"] = "nodes_nature:limestone"}, {["x"] = 1, ["y"] = 1, ["z"] = 2, ["name"] = "nodes_nature:limestone"}, {["x"] = 1, ["y"] = 1, ["z"] = 3, ["name"] = "nodes_nature:limestone"}, {["x"] = 1, ["y"] = 1, ["z"] = 4, ["name"] = "nodes_nature:limestone"}, {["x"] = 1, ["y"] = 1, ["z"] = 5, ["name"] = "nodes_nature:limestone"}, {["x"] = 1, ["y"] = 1, ["z"] = 6, ["name"] = "nodes_nature:limestone"}, {["x"] = 1, ["y"] = 1, ["z"] = 7, ["name"] = "nodes_nature:limestone"}, {["x"] = 1, ["y"] = 1, ["z"] = 8, ["name"] = "nodes_nature:limestone"}, {["x"] = 1, ["y"] = 1, ["z"] = 9, ["name"] = "nodes_nature:limestone"}, {["x"] = 1, ["y"] = 1, ["z"] = 10, ["name"] = "nodes_nature:limestone"}, {["x"] = 1, ["y"] = 1, ["z"] = 11, ["name"] = "nodes_nature:limestone"}, {["x"] = 1, ["y"] = 1, ["z"] = 12, ["name"] = "nodes_nature:limestone"}, {["x"] = 1, ["y"] = 1, ["z"] = 13, ["name"] = "nodes_nature:limestone"}, {["x"] = 1, ["y"] = 1, ["z"] = 14, ["name"] = "nodes_nature:limestone"}, {["x"] = 1, ["y"] = 1, ["z"] = 15, ["name"] = "nodes_nature:limestone"}, {["x"] = 1, ["y"] = 1, ["z"] = 16, ["name"] = "nodes_nature:limestone"}, {["x"] = 1, ["y"] = 1, ["z"] = 17, ["name"] = "nodes_nature:sand_wet_salty"}, {["x"] = 1, ["y"] = 1, ["z"] = 18, ["name"] = "nodes_nature:sand_wet_salty"}, {["x"] = 1, ["y"] = 2, ["z"] = 0, ["name"] = "nodes_nature:limestone"}, {["x"] = 1, ["y"] = 2, ["z"] = 1, ["name"] = "nodes_nature:limestone"}, {["x"] = 1, ["y"] = 2, ["z"] = 2, ["name"] = "nodes_nature:limestone"}, {["x"] = 1, ["y"] = 2, ["z"] = 3, ["name"] = "nodes_nature:limestone"}, {["x"] = 1, ["y"] = 2, ["z"] = 4, ["name"] = "nodes_nature:limestone"}, {["x"] = 1, ["y"] = 2, ["z"] = 5, ["name"] = "nodes_nature:limestone"}, {["x"] = 1, ["y"] = 2, ["z"] = 6, ["name"] = "nodes_nature:limestone"}, {["x"] = 1, ["y"] = 2, ["z"] = 7, ["name"] = "nodes_nature:limestone"}, {["x"] = 1, ["y"] = 2, ["z"] = 8, ["name"] = "nodes_nature:limestone"}, {["x"] = 1, ["y"] = 2, ["z"] = 9, ["name"] = "nodes_nature:limestone"}, {["x"] = 1, ["y"] = 2, ["z"] = 10, ["name"] = "nodes_nature:limestone"}, {["x"] = 1, ["y"] = 2, ["z"] = 11, ["name"] = "nodes_nature:limestone"}, {["x"] = 1, ["y"] = 2, ["z"] = 12, ["name"] = "nodes_nature:limestone"}, {["x"] = 1, ["y"] = 2, ["z"] = 13, ["name"] = "nodes_nature:sand_wet_salty"}, {["x"] = 1, ["y"] = 2, ["z"] = 14, ["name"] = "nodes_nature:sand_wet_salty"}, {["x"] = 1, ["y"] = 2, ["z"] = 15, ["name"] = "nodes_nature:sand_wet_salty"}, {["x"] = 1, ["y"] = 2, ["z"] = 16, ["name"] = "nodes_nature:sand_wet_salty"}, {["x"] = 1, ["y"] = 2, ["z"] = 17, ["name"] = "nodes_nature:sand_wet_salty"}, {["x"] = 1, ["y"] = 2, ["z"] = 18, ["name"] = "nodes_nature:sand_wet_salty"}, {["x"] = 1, ["y"] = 3, ["z"] = 0, ["name"] = "nodes_nature:limestone"}, {["x"] = 1, ["y"] = 3, ["z"] = 1, ["name"] = "nodes_nature:limestone"}, {["x"] = 1, ["y"] = 3, ["z"] = 2, ["name"] = "nodes_nature:limestone"}, {["x"] = 1, ["y"] = 3, ["z"] = 3, ["name"] = "nodes_nature:limestone"}, {["x"] = 1, ["y"] = 3, ["z"] = 4, ["name"] = "nodes_nature:limestone"}, {["x"] = 1, ["y"] = 3, ["z"] = 5, ["name"] = "nodes_nature:limestone"}, {["x"] = 1, ["y"] = 3, ["z"] = 6, ["name"] = "nodes_nature:limestone"}, {["x"] = 1, ["y"] = 3, ["z"] = 7, ["name"] = "nodes_nature:limestone"}, {["x"] = 1, ["y"] = 3, ["z"] = 8, ["name"] = "nodes_nature:limestone"}, {["x"] = 1, ["y"] = 3, ["z"] = 9, ["name"] = "nodes_nature:sand_wet_salty"}, {["x"] = 1, ["y"] = 3, ["z"] = 10, ["name"] = "nodes_nature:sand_wet_salty"}, {["x"] = 1, ["y"] = 3, ["z"] = 11, ["name"] = "nodes_nature:sand_wet_salty"}, {["x"] = 1, ["y"] = 3, ["z"] = 12, ["name"] = "nodes_nature:sand_wet_salty"}, {["x"] = 1, ["y"] = 3, ["z"] = 13, ["name"] = "nodes_nature:sand_wet_salty"}, {["x"] = 1, ["y"] = 3, ["z"] = 14, ["name"] = "nodes_nature:sand_wet_salty"}, {["x"] = 1, ["y"] = 3, ["z"] = 15, ["name"] = "nodes_nature:sand_wet_salty"}, {["x"] = 1, ["y"] = 3, ["z"] = 16, ["name"] = "nodes_nature:sand_wet_salty"}, {["x"] = 1, ["y"] = 3, ["z"] = 17, ["name"] = "nodes_nature:sand_wet_salty"}, {["x"] = 1, ["y"] = 3, ["z"] = 18, ["name"] = "nodes_nature:sand_wet_salty"}, {["x"] = 1, ["y"] = 4, ["z"] = 0, ["name"] = "nodes_nature:limestone"}, {["x"] = 1, ["y"] = 4, ["z"] = 1, ["name"] = "nodes_nature:limestone"}, {["x"] = 1, ["y"] = 4, ["z"] = 2, ["name"] = "nodes_nature:limestone"}, {["x"] = 1, ["y"] = 4, ["z"] = 3, ["name"] = "nodes_nature:limestone"}, {["x"] = 1, ["y"] = 4, ["z"] = 4, ["name"] = "nodes_nature:limestone"}, {["x"] = 1, ["y"] = 4, ["z"] = 5, ["name"] = "nodes_nature:limestone"}, {["x"] = 1, ["y"] = 4, ["z"] = 6, ["name"] = "nodes_nature:sand_wet_salty"}, {["x"] = 1, ["y"] = 4, ["z"] = 7, ["name"] = "nodes_nature:sand_wet_salty"}, {["x"] = 1, ["y"] = 4, ["z"] = 8, ["name"] = "nodes_nature:sand_wet_salty"}, {["x"] = 1, ["y"] = 4, ["z"] = 9, ["name"] = "nodes_nature:sand_wet_salty"}, {["x"] = 1, ["y"] = 4, ["z"] = 10, ["name"] = "nodes_nature:sand_wet_salty"}, {["x"] = 1, ["y"] = 4, ["z"] = 11, ["name"] = "nodes_nature:sand_wet_salty"}, {["x"] = 1, ["y"] = 4, ["z"] = 12, ["name"] = "nodes_nature:sand_wet_salty"}, {["x"] = 1, ["y"] = 4, ["z"] = 13, ["name"] = "nodes_nature:sand_wet_salty"}, {["x"] = 1, ["y"] = 4, ["z"] = 14, ["name"] = "nodes_nature:sand_wet_salty"}, {["x"] = 1, ["y"] = 4, ["z"] = 15, ["name"] = "nodes_nature:sand_wet_salty"}, {["x"] = 1, ["y"] = 4, ["z"] = 16, ["name"] = "nodes_nature:sand_wet_salty"}, {["x"] = 1, ["y"] = 4, ["param1"] = 189, ["z"] = 17, ["name"] = "nodes_nature:salt_water_source"}, {["x"] = 1, ["y"] = 4, ["param1"] = 172, ["z"] = 18, ["name"] = "nodes_nature:salt_water_source"}, {["x"] = 1, ["y"] = 5, ["z"] = 0, ["name"] = "nodes_nature:limestone"}, {["x"] = 1, ["y"] = 5, ["z"] = 1, ["name"] = "nodes_nature:limestone"}, {["x"] = 1, ["y"] = 5, ["z"] = 2, ["name"] = "nodes_nature:limestone"}, {["x"] = 1, ["y"] = 5, ["z"] = 3, ["name"] = "nodes_nature:limestone"}, {["x"] = 1, ["y"] = 5, ["z"] = 4, ["name"] = "nodes_nature:sand_wet_salty"}, {["x"] = 1, ["y"] = 5, ["z"] = 5, ["name"] = "nodes_nature:sand_wet_salty"}, {["x"] = 1, ["y"] = 5, ["z"] = 6, ["name"] = "nodes_nature:sand_wet_salty"}, {["x"] = 1, ["y"] = 5, ["z"] = 7, ["name"] = "nodes_nature:sand_wet_salty"}, {["x"] = 1, ["y"] = 5, ["z"] = 8, ["name"] = "nodes_nature:sand_wet_salty"}, {["x"] = 1, ["y"] = 5, ["z"] = 9, ["name"] = "nodes_nature:sand_wet_salty"}, {["x"] = 1, ["y"] = 5, ["z"] = 10, ["name"] = "nodes_nature:sand_wet_salty"}, {["x"] = 1, ["y"] = 5, ["z"] = 11, ["name"] = "nodes_nature:sand_wet_salty"}, {["x"] = 1, ["y"] = 5, ["z"] = 12, ["name"] = "nodes_nature:sand_wet_salty"}, {["x"] = 1, ["meta"] = {["fields"] = {["owner"] = "singleplayer", ["infotext"] = "\27(T@tech)Clear Glass Window\27E\
Owned by singleplayer"}, ["inventory"] = {}}, ["param2"] = 3, ["y"] = 5, ["param1"] = 159, ["z"] = 13, ["name"] = "tech:window_clear"}, {["x"] = 1, ["meta"] = {["fields"] = {["owner"] = "singleplayer", ["infotext"] = "\27(T@tech)Clear Glass Window\27E\
Owned by singleplayer"}, ["inventory"] = {}}, ["param2"] = 3, ["y"] = 5, ["param1"] = 159, ["z"] = 14, ["name"] = "tech:window_clear"}, {["x"] = 1, ["meta"] = {["fields"] = {["owner"] = "singleplayer", ["infotext"] = "\27(T@tech)Clear Glass Window\27E\
Owned by singleplayer"}, ["inventory"] = {}}, ["param2"] = 3, ["y"] = 5, ["param1"] = 175, ["z"] = 15, ["name"] = "tech:window_clear"}, {["x"] = 1, ["param2"] = 2, ["y"] = 5, ["z"] = 16, ["name"] = "nodes_nature:basalt_brick"}, {["x"] = 1, ["y"] = 5, ["param1"] = 205, ["z"] = 17, ["name"] = "nodes_nature:salt_water_source"}, {["x"] = 1, ["y"] = 5, ["param1"] = 188, ["z"] = 18, ["name"] = "nodes_nature:salt_water_source"}, {["x"] = 1, ["y"] = 6, ["z"] = 0, ["name"] = "nodes_nature:limestone"}, {["x"] = 1, ["y"] = 6, ["z"] = 1, ["name"] = "nodes_nature:limestone"}, {["x"] = 1, ["y"] = 6, ["z"] = 2, ["name"] = "nodes_nature:sand_wet_salty"}, {["x"] = 1, ["y"] = 6, ["z"] = 3, ["name"] = "nodes_nature:sand_wet_salty"}, {["x"] = 1, ["y"] = 6, ["z"] = 4, ["name"] = "nodes_nature:sand_wet_salty"}, {["x"] = 1, ["y"] = 6, ["z"] = 5, ["name"] = "nodes_nature:sand_wet_salty"}, {["x"] = 1, ["y"] = 6, ["z"] = 6, ["name"] = "nodes_nature:sand_wet_salty"}, {["x"] = 1, ["y"] = 6, ["z"] = 7, ["name"] = "nodes_nature:sand_wet_salty"}, {["x"] = 1, ["y"] = 6, ["z"] = 8, ["name"] = "nodes_nature:sand_wet_salty"}, {["x"] = 1, ["meta"] = {["fields"] = {["infotext"] = "\27(T@tech)Clear Glass Window\27E\
Owned by singleplayer", ["owner"] = "singleplayer"}, ["inventory"] = {}}, ["param2"] = 3, ["y"] = 6, ["param1"] = 175, ["z"] = 9, ["name"] = "tech:window_clear"}, {["x"] = 1, ["meta"] = {["fields"] = {["infotext"] = "\27(T@tech)Clear Glass Window\27E\
Owned by singleplayer", ["owner"] = "singleplayer"}, ["inventory"] = {}}, ["param2"] = 1, ["y"] = 6, ["param1"] = 159, ["z"] = 10, ["name"] = "tech:window_clear"}, {["x"] = 1, ["meta"] = {["fields"] = {["infotext"] = "\27(T@tech)Clear Glass Window\27E\
Owned by singleplayer", ["owner"] = "singleplayer"}, ["inventory"] = {}}, ["param2"] = 3, ["y"] = 6, ["param1"] = 143, ["z"] = 11, ["name"] = "tech:window_clear"}, {["x"] = 1, ["meta"] = {["fields"] = {["owner"] = "singleplayer", ["infotext"] = "\27(T@tech)Clear Glass Window\27E\
Owned by singleplayer"}, ["inventory"] = {}}, ["param2"] = 3, ["y"] = 6, ["param1"] = 159, ["z"] = 12, ["name"] = "tech:window_clear"}, {["x"] = 1, ["meta"] = {["fields"] = {["owner"] = "singleplayer", ["infotext"] = "\27(T@tech)Clear Glass Window\27E\
Owned by singleplayer"}, ["inventory"] = {}}, ["param2"] = 3, ["y"] = 6, ["param1"] = 175, ["z"] = 13, ["name"] = "tech:window_clear"}, {["x"] = 1, ["meta"] = {["fields"] = {["owner"] = "singleplayer", ["infotext"] = "\27(T@tech)Clear Glass Window\27E\
Owned by singleplayer"}, ["inventory"] = {}}, ["param2"] = 1, ["y"] = 6, ["param1"] = 159, ["z"] = 14, ["name"] = "tech:window_clear"}, {["x"] = 1, ["meta"] = {["fields"] = {["owner"] = "singleplayer", ["infotext"] = "\27(T@tech)Clear Glass Window\27E\
Owned by singleplayer"}, ["inventory"] = {}}, ["param2"] = 3, ["y"] = 6, ["param1"] = 159, ["z"] = 15, ["name"] = "tech:window_clear"}, {["x"] = 1, ["param2"] = 2, ["y"] = 6, ["z"] = 16, ["name"] = "nodes_nature:basalt_brick"}, {["x"] = 1, ["y"] = 6, ["param1"] = 189, ["z"] = 17, ["name"] = "nodes_nature:salt_water_source"}, {["x"] = 1, ["y"] = 6, ["param1"] = 172, ["z"] = 18, ["name"] = "nodes_nature:salt_water_source"}, {["x"] = 1, ["y"] = 7, ["z"] = 0, ["name"] = "nodes_nature:sand_wet_salty"}, {["x"] = 1, ["y"] = 7, ["z"] = 1, ["name"] = "nodes_nature:sand_wet_salty"}, {["x"] = 1, ["y"] = 7, ["z"] = 2, ["name"] = "nodes_nature:sand_wet_salty"}, {["x"] = 1, ["y"] = 7, ["z"] = 3, ["name"] = "nodes_nature:sand_wet_salty"}, {["x"] = 1, ["y"] = 7, ["z"] = 4, ["name"] = "nodes_nature:sand_wet_salty"}, {["x"] = 1, ["y"] = 7, ["z"] = 5, ["name"] = "nodes_nature:sand_wet_salty"}, {["x"] = 1, ["meta"] = {["fields"] = {["infotext"] = "\27(T@tech)Clear Glass Window\27E\
Owned by singleplayer", ["owner"] = "singleplayer"}, ["inventory"] = {}}, ["param2"] = 3, ["y"] = 7, ["param1"] = 175, ["z"] = 6, ["name"] = "tech:window_clear"}, {["x"] = 1, ["meta"] = {["fields"] = {["infotext"] = "\27(T@tech)Clear Glass Window\27E\
Owned by singleplayer", ["owner"] = "singleplayer"}, ["inventory"] = {}}, ["param2"] = 3, ["y"] = 7, ["param1"] = 159, ["z"] = 7, ["name"] = "tech:window_clear"}, {["x"] = 1, ["meta"] = {["fields"] = {["infotext"] = "\27(T@tech)Clear Glass Window\27E\
Owned by singleplayer", ["owner"] = "singleplayer"}, ["inventory"] = {}}, ["param2"] = 3, ["y"] = 7, ["param1"] = 175, ["z"] = 8, ["name"] = "tech:window_clear"}, {["x"] = 1, ["meta"] = {["fields"] = {["infotext"] = "\27(T@tech)Clear Glass Window\27E\
Owned by singleplayer", ["owner"] = "singleplayer"}, ["inventory"] = {}}, ["param2"] = 3, ["y"] = 7, ["param1"] = 191, ["z"] = 9, ["name"] = "tech:window_clear"}, {["x"] = 1, ["meta"] = {["fields"] = {["infotext"] = "\27(T@tech)Clear Glass Window\27E\
Owned by singleplayer", ["owner"] = "singleplayer"}, ["inventory"] = {}}, ["param2"] = 3, ["y"] = 7, ["param1"] = 175, ["z"] = 10, ["name"] = "tech:window_clear"}, {["x"] = 1, ["meta"] = {["fields"] = {["infotext"] = "\27(T@tech)Clear Glass Window\27E\
Owned by singleplayer", ["owner"] = "singleplayer"}, ["inventory"] = {}}, ["param2"] = 3, ["y"] = 7, ["param1"] = 159, ["z"] = 11, ["name"] = "tech:window_clear"}, {["x"] = 1, ["meta"] = {["fields"] = {["owner"] = "singleplayer", ["infotext"] = "\27(T@tech)Clear Glass Window\27E\
Owned by singleplayer"}, ["inventory"] = {}}, ["param2"] = 3, ["y"] = 7, ["param1"] = 175, ["z"] = 12, ["name"] = "tech:window_clear"}, {["x"] = 1, ["meta"] = {["fields"] = {["owner"] = "singleplayer", ["infotext"] = "\27(T@tech)Clear Glass Window\27E\
Owned by singleplayer"}, ["inventory"] = {}}, ["param2"] = 3, ["y"] = 7, ["param1"] = 191, ["z"] = 13, ["name"] = "tech:window_clear"}, {["x"] = 1, ["meta"] = {["fields"] = {["owner"] = "singleplayer", ["infotext"] = "\27(T@tech)Clear Glass Window\27E\
Owned by singleplayer"}, ["inventory"] = {}}, ["param2"] = 3, ["y"] = 7, ["param1"] = 175, ["z"] = 14, ["name"] = "tech:window_clear"}, {["x"] = 1, ["meta"] = {["fields"] = {["owner"] = "singleplayer", ["infotext"] = "\27(T@tech)Clear Glass Window\27E\
Owned by singleplayer"}, ["inventory"] = {}}, ["param2"] = 3, ["y"] = 7, ["param1"] = 159, ["z"] = 15, ["name"] = "tech:window_clear"}, {["x"] = 1, ["param2"] = 2, ["y"] = 7, ["z"] = 16, ["name"] = "nodes_nature:basalt_brick"}, {["x"] = 1, ["y"] = 7, ["param1"] = 173, ["z"] = 17, ["name"] = "nodes_nature:salt_water_source"}, {["x"] = 1, ["y"] = 7, ["param1"] = 156, ["z"] = 18, ["name"] = "nodes_nature:salt_water_source"}, {["x"] = 1, ["y"] = 8, ["z"] = 0, ["name"] = "nodes_nature:sand_wet_salty"}, {["x"] = 1, ["y"] = 8, ["z"] = 1, ["name"] = "nodes_nature:sand_wet_salty"}, {["x"] = 1, ["y"] = 8, ["z"] = 2, ["name"] = "nodes_nature:sand_wet_salty"}, {["x"] = 1, ["y"] = 8, ["z"] = 3, ["name"] = "nodes_nature:sand_wet_salty"}, {["x"] = 1, ["meta"] = {["fields"] = {["infotext"] = "\27(T@tech)Clear Glass Window\27E\
Owned by singleplayer", ["owner"] = "singleplayer"}, ["inventory"] = {}}, ["param2"] = 3, ["y"] = 8, ["param1"] = 159, ["z"] = 4, ["name"] = "tech:window_clear"}, {["x"] = 1, ["meta"] = {["fields"] = {["infotext"] = "\27(T@tech)Clear Glass Window\27E\
Owned by singleplayer", ["owner"] = "singleplayer"}, ["inventory"] = {}}, ["param2"] = 3, ["y"] = 8, ["param1"] = 175, ["z"] = 5, ["name"] = "tech:window_clear"}, {["x"] = 1, ["meta"] = {["fields"] = {["infotext"] = "\27(T@tech)Clear Glass Window\27E\
Owned by singleplayer", ["owner"] = "singleplayer"}, ["inventory"] = {}}, ["param2"] = 3, ["y"] = 8, ["param1"] = 191, ["z"] = 6, ["name"] = "tech:window_clear"}, {["x"] = 1, ["meta"] = {["fields"] = {["infotext"] = "\27(T@tech)Clear Glass Window\27E\
Owned by singleplayer", ["owner"] = "singleplayer"}, ["inventory"] = {}}, ["param2"] = 3, ["y"] = 8, ["param1"] = 175, ["z"] = 7, ["name"] = "tech:window_clear"}, {["x"] = 1, ["meta"] = {["fields"] = {["infotext"] = "\27(T@tech)Clear Glass Window\27E\
Owned by singleplayer", ["owner"] = "singleplayer"}, ["inventory"] = {}}, ["param2"] = 3, ["y"] = 8, ["param1"] = 191, ["z"] = 8, ["name"] = "tech:window_clear"}, {["x"] = 1, ["meta"] = {["fields"] = {["infotext"] = "\27(T@tech)Clear Glass Window\27E\
Owned by singleplayer", ["owner"] = "singleplayer"}, ["inventory"] = {}}, ["param2"] = 3, ["y"] = 8, ["param1"] = 207, ["z"] = 9, ["name"] = "tech:window_clear"}, {["x"] = 1, ["meta"] = {["fields"] = {["infotext"] = "\27(T@tech)Clear Glass Window\27E\
Owned by singleplayer", ["owner"] = "singleplayer"}, ["inventory"] = {}}, ["param2"] = 3, ["y"] = 8, ["param1"] = 191, ["z"] = 10, ["name"] = "tech:window_clear"}, {["x"] = 1, ["meta"] = {["fields"] = {["infotext"] = "\27(T@tech)Clear Glass Window\27E\
Owned by singleplayer", ["owner"] = "singleplayer"}, ["inventory"] = {}}, ["param2"] = 3, ["y"] = 8, ["param1"] = 175, ["z"] = 11, ["name"] = "tech:window_clear"}, {["x"] = 1, ["meta"] = {["fields"] = {["owner"] = "singleplayer", ["infotext"] = "\27(T@tech)Clear Glass Window\27E\
Owned by singleplayer"}, ["inventory"] = {}}, ["param2"] = 3, ["y"] = 8, ["param1"] = 191, ["z"] = 12, ["name"] = "tech:window_clear"}, {["x"] = 1, ["meta"] = {["fields"] = {["owner"] = "singleplayer", ["infotext"] = "\27(T@tech)Clear Glass Window\27E\
Owned by singleplayer"}, ["inventory"] = {}}, ["param2"] = 3, ["y"] = 8, ["param1"] = 207, ["z"] = 13, ["name"] = "tech:window_clear"}, {["x"] = 1, ["meta"] = {["fields"] = {["owner"] = "singleplayer", ["infotext"] = "\27(T@tech)Clear Glass Window\27E\
Owned by singleplayer"}, ["inventory"] = {}}, ["param2"] = 5, ["y"] = 8, ["param1"] = 191, ["z"] = 14, ["name"] = "tech:window_clear"}, {["x"] = 1, ["meta"] = {["fields"] = {["owner"] = "singleplayer", ["infotext"] = "\27(T@tech)Clear Glass Window\27E\
Owned by singleplayer"}, ["inventory"] = {}}, ["param2"] = 3, ["y"] = 8, ["param1"] = 175, ["z"] = 15, ["name"] = "tech:window_clear"}, {["x"] = 1, ["param2"] = 2, ["y"] = 8, ["z"] = 16, ["name"] = "nodes_nature:basalt_brick"}, {["x"] = 1, ["y"] = 8, ["param1"] = 157, ["z"] = 17, ["name"] = "nodes_nature:salt_water_source"}, {["x"] = 1, ["y"] = 8, ["param1"] = 140, ["z"] = 18, ["name"] = "nodes_nature:salt_water_source"}, {["x"] = 1, ["y"] = 9, ["z"] = 0, ["name"] = "nodes_nature:basalt"}, {["x"] = 1, ["y"] = 9, ["z"] = 1, ["name"] = "nodes_nature:basalt"}, {["x"] = 1, ["meta"] = {["fields"] = {["owner"] = "singleplayer", ["infotext"] = "\27(T@tech)Clear Glass Window\27E\
Owned by singleplayer"}, ["inventory"] = {}}, ["param2"] = 21, ["y"] = 9, ["param1"] = 175, ["z"] = 2, ["name"] = "tech:window_clear"}, {["x"] = 1, ["meta"] = {["fields"] = {["owner"] = "singleplayer", ["infotext"] = "\27(T@tech)Clear Glass Window\27E\
Owned by singleplayer"}, ["inventory"] = {}}, ["param2"] = 9, ["y"] = 9, ["param1"] = 159, ["z"] = 3, ["name"] = "tech:window_clear"}, {["x"] = 1, ["meta"] = {["fields"] = {["owner"] = "singleplayer", ["infotext"] = "\27(T@tech)Clear Glass Window\27E\
Owned by singleplayer"}, ["inventory"] = {}}, ["param2"] = 3, ["y"] = 9, ["param1"] = 175, ["z"] = 4, ["name"] = "tech:window_clear"}, {["x"] = 1, ["meta"] = {["fields"] = {["owner"] = "singleplayer", ["infotext"] = "\27(T@tech)Clear Glass Window\27E\
Owned by singleplayer"}, ["inventory"] = {}}, ["param2"] = 3, ["y"] = 9, ["param1"] = 191, ["z"] = 5, ["name"] = "tech:window_clear"}, {["x"] = 1, ["meta"] = {["fields"] = {["owner"] = "singleplayer", ["infotext"] = "\27(T@tech)Clear Glass Window\27E\
Owned by singleplayer"}, ["inventory"] = {}}, ["param2"] = 3, ["y"] = 9, ["param1"] = 207, ["z"] = 6, ["name"] = "tech:window_clear"}, {["x"] = 1, ["meta"] = {["fields"] = {["owner"] = "singleplayer", ["infotext"] = "\27(T@tech)Clear Glass Window\27E\
Owned by singleplayer"}, ["inventory"] = {}}, ["param2"] = 3, ["y"] = 9, ["param1"] = 191, ["z"] = 7, ["name"] = "tech:window_clear"}, {["x"] = 1, ["meta"] = {["fields"] = {["owner"] = "singleplayer", ["infotext"] = "\27(T@tech)Clear Glass Window\27E\
Owned by singleplayer"}, ["inventory"] = {}}, ["param2"] = 3, ["y"] = 9, ["param1"] = 175, ["z"] = 8, ["name"] = "tech:window_clear"}, {["x"] = 1, ["meta"] = {["fields"] = {["owner"] = "singleplayer", ["infotext"] = "\27(T@tech)Clear Glass Window\27E\
Owned by singleplayer"}, ["inventory"] = {}}, ["param2"] = 3, ["y"] = 9, ["param1"] = 191, ["z"] = 9, ["name"] = "tech:window_clear"}, {["x"] = 1, ["meta"] = {["fields"] = {["owner"] = "singleplayer", ["infotext"] = "\27(T@tech)Clear Glass Window\27E\
Owned by singleplayer"}, ["inventory"] = {}}, ["param2"] = 3, ["y"] = 9, ["param1"] = 175, ["z"] = 10, ["name"] = "tech:window_clear"}, {["x"] = 1, ["meta"] = {["fields"] = {["owner"] = "singleplayer", ["infotext"] = "\27(T@tech)Clear Glass Window\27E\
Owned by singleplayer"}, ["inventory"] = {}}, ["param2"] = 3, ["y"] = 9, ["param1"] = 159, ["z"] = 11, ["name"] = "tech:window_clear"}, {["x"] = 1, ["meta"] = {["fields"] = {["owner"] = "singleplayer", ["infotext"] = "\27(T@tech)Clear Glass Window\27E\
Owned by singleplayer"}, ["inventory"] = {}}, ["param2"] = 3, ["y"] = 9, ["param1"] = 175, ["z"] = 12, ["name"] = "tech:window_clear"}, {["x"] = 1, ["meta"] = {["fields"] = {["owner"] = "singleplayer", ["infotext"] = "\27(T@tech)Clear Glass Window\27E\
Owned by singleplayer"}, ["inventory"] = {}}, ["param2"] = 3, ["y"] = 9, ["param1"] = 191, ["z"] = 13, ["name"] = "tech:window_clear"}, {["x"] = 1, ["meta"] = {["fields"] = {["owner"] = "singleplayer", ["infotext"] = "\27(T@tech)Clear Glass Window\27E\
Owned by singleplayer"}, ["inventory"] = {}}, ["param2"] = 5, ["y"] = 9, ["param1"] = 175, ["z"] = 14, ["name"] = "tech:window_clear"}, {["x"] = 1, ["meta"] = {["fields"] = {["owner"] = "singleplayer", ["infotext"] = "\27(T@tech)Clear Glass Window\27E\
Owned by singleplayer"}, ["inventory"] = {}}, ["param2"] = 3, ["y"] = 9, ["param1"] = 159, ["z"] = 15, ["name"] = "tech:window_clear"}, {["x"] = 1, ["param2"] = 2, ["y"] = 9, ["z"] = 16, ["name"] = "nodes_nature:basalt_brick"}, {["x"] = 1, ["y"] = 9, ["param1"] = 157, ["z"] = 17, ["name"] = "nodes_nature:salt_water_source"}, {["x"] = 1, ["y"] = 9, ["param1"] = 141, ["z"] = 18, ["name"] = "nodes_nature:salt_water_source"}, {["x"] = 1, ["y"] = 10, ["param1"] = 190, ["z"] = 0, ["name"] = "nodes_nature:salt_water_source"}, {["x"] = 1, ["param2"] = 3, ["y"] = 10, ["z"] = 1, ["name"] = "nodes_nature:basalt_brick"}, {["x"] = 1, ["meta"] = {["fields"] = {["owner"] = "singleplayer", ["infotext"] = "\27(T@tech)Clear Glass Window\27E\
Owned by singleplayer"}, ["inventory"] = {}}, ["param2"] = 3, ["y"] = 10, ["param1"] = 191, ["z"] = 2, ["name"] = "tech:window_clear"}, {["x"] = 1, ["meta"] = {["fields"] = {["owner"] = "singleplayer", ["infotext"] = "\27(T@tech)Clear Glass Window\27E\
Owned by singleplayer"}, ["inventory"] = {}}, ["param2"] = 3, ["y"] = 10, ["param1"] = 175, ["z"] = 3, ["name"] = "tech:window_clear"}, {["x"] = 1, ["meta"] = {["fields"] = {["owner"] = "singleplayer", ["infotext"] = "\27(T@tech)Clear Glass Window\27E\
Owned by singleplayer"}, ["inventory"] = {}}, ["param2"] = 3, ["y"] = 10, ["param1"] = 159, ["z"] = 4, ["name"] = "tech:window_clear"}, {["x"] = 1, ["meta"] = {["fields"] = {["owner"] = "singleplayer", ["infotext"] = "\27(T@tech)Clear Glass Window\27E\
Owned by singleplayer"}, ["inventory"] = {}}, ["param2"] = 3, ["y"] = 10, ["param1"] = 175, ["z"] = 5, ["name"] = "tech:window_clear"}, {["x"] = 1, ["meta"] = {["fields"] = {["owner"] = "singleplayer", ["infotext"] = "\27(T@tech)Clear Glass Window\27E\
Owned by singleplayer"}, ["inventory"] = {}}, ["param2"] = 3, ["y"] = 10, ["param1"] = 191, ["z"] = 6, ["name"] = "tech:window_clear"}, {["x"] = 1, ["meta"] = {["fields"] = {["owner"] = "singleplayer", ["infotext"] = "\27(T@tech)Clear Glass Window\27E\
Owned by singleplayer"}, ["inventory"] = {}}, ["param2"] = 3, ["y"] = 10, ["param1"] = 175, ["z"] = 7, ["name"] = "tech:window_clear"}, {["x"] = 1, ["meta"] = {["fields"] = {["owner"] = "singleplayer", ["infotext"] = "\27(T@tech)Clear Glass Window\27E\
Owned by singleplayer"}, ["inventory"] = {}}, ["param2"] = 3, ["y"] = 10, ["param1"] = 159, ["z"] = 8, ["name"] = "tech:window_clear"}, {["x"] = 1, ["meta"] = {["fields"] = {["owner"] = "singleplayer", ["infotext"] = "\27(T@tech)Clear Glass Window\27E\
Owned by singleplayer"}, ["inventory"] = {}}, ["param2"] = 3, ["y"] = 10, ["param1"] = 175, ["z"] = 9, ["name"] = "tech:window_clear"}, {["x"] = 1, ["meta"] = {["fields"] = {["owner"] = "singleplayer", ["infotext"] = "\27(T@tech)Clear Glass Window\27E\
Owned by singleplayer"}, ["inventory"] = {}}, ["param2"] = 3, ["y"] = 10, ["param1"] = 159, ["z"] = 10, ["name"] = "tech:window_clear"}, {["x"] = 1, ["meta"] = {["fields"] = {["owner"] = "singleplayer", ["infotext"] = "\27(T@tech)Clear Glass Window\27E\
Owned by singleplayer"}, ["inventory"] = {}}, ["param2"] = 3, ["y"] = 10, ["param1"] = 143, ["z"] = 11, ["name"] = "tech:window_clear"}, {["x"] = 1, ["meta"] = {["fields"] = {["owner"] = "singleplayer", ["infotext"] = "\27(T@tech)Clear Glass Window\27E\
Owned by singleplayer"}, ["inventory"] = {}}, ["param2"] = 3, ["y"] = 10, ["param1"] = 159, ["z"] = 12, ["name"] = "tech:window_clear"}, {["x"] = 1, ["meta"] = {["fields"] = {["owner"] = "singleplayer", ["infotext"] = "\27(T@tech)Clear Glass Window\27E\
Owned by singleplayer"}, ["inventory"] = {}}, ["param2"] = 3, ["y"] = 10, ["param1"] = 175, ["z"] = 13, ["name"] = "tech:window_clear"}, {["x"] = 1, ["meta"] = {["fields"] = {["owner"] = "singleplayer", ["infotext"] = "\27(T@tech)Clear Glass Window\27E\
Owned by singleplayer"}, ["inventory"] = {}}, ["param2"] = 3, ["y"] = 10, ["param1"] = 159, ["z"] = 14, ["name"] = "tech:window_clear"}, {["x"] = 1, ["meta"] = {["fields"] = {["owner"] = "singleplayer", ["infotext"] = "\27(T@tech)Clear Glass Window\27E\
Owned by singleplayer"}, ["inventory"] = {}}, ["param2"] = 3, ["y"] = 10, ["param1"] = 175, ["z"] = 15, ["name"] = "tech:window_clear"}, {["x"] = 1, ["param2"] = 2, ["y"] = 10, ["z"] = 16, ["name"] = "nodes_nature:basalt_brick"}, {["x"] = 1, ["y"] = 10, ["param1"] = 174, ["z"] = 17, ["name"] = "nodes_nature:salt_water_source"}, {["x"] = 1, ["y"] = 10, ["param1"] = 158, ["z"] = 18, ["name"] = "nodes_nature:salt_water_source"}, {["x"] = 1, ["meta"] = {["fields"] = {["owner"] = "singleplayer", ["infotext"] = "Sun Stone\
Owned by singleplayer"}, ["inventory"] = {}}, ["param2"] = 1, ["y"] = 11, ["param1"] = 223, ["z"] = 1, ["name"] = "artifacts:sun_stone"}, {["x"] = 1, ["param2"] = 2, ["y"] = 11, ["z"] = 16, ["name"] = "nodes_nature:basalt_brick"}, {["x"] = 1, ["meta"] = {["fields"] = {["owner"] = "singleplayer", ["infotext"] = "Sun Stone\
Owned by singleplayer"}, ["inventory"] = {}}, ["param2"] = 1, ["y"] = 12, ["param1"] = 223, ["z"] = 16, ["name"] = "artifacts:sun_stone"}, {["x"] = 2, ["y"] = 0, ["z"] = 0, ["name"] = "nodes_nature:limestone"}, {["x"] = 2, ["y"] = 0, ["z"] = 1, ["name"] = "nodes_nature:limestone"}, {["x"] = 2, ["y"] = 0, ["z"] = 2, ["name"] = "nodes_nature:limestone"}, {["x"] = 2, ["y"] = 0, ["z"] = 3, ["name"] = "nodes_nature:limestone"}, {["x"] = 2, ["y"] = 0, ["z"] = 4, ["name"] = "nodes_nature:limestone"}, {["x"] = 2, ["y"] = 0, ["z"] = 5, ["name"] = "nodes_nature:limestone"}, {["x"] = 2, ["y"] = 0, ["z"] = 6, ["name"] = "nodes_nature:limestone"}, {["x"] = 2, ["y"] = 0, ["z"] = 7, ["name"] = "nodes_nature:limestone"}, {["x"] = 2, ["y"] = 0, ["z"] = 8, ["name"] = "nodes_nature:limestone"}, {["x"] = 2, ["y"] = 0, ["z"] = 9, ["name"] = "nodes_nature:limestone"}, {["x"] = 2, ["y"] = 0, ["z"] = 10, ["name"] = "nodes_nature:limestone"}, {["x"] = 2, ["y"] = 0, ["z"] = 11, ["name"] = "nodes_nature:limestone"}, {["x"] = 2, ["y"] = 0, ["z"] = 12, ["name"] = "nodes_nature:limestone"}, {["x"] = 2, ["y"] = 0, ["z"] = 13, ["name"] = "nodes_nature:limestone"}, {["x"] = 2, ["y"] = 0, ["z"] = 14, ["name"] = "nodes_nature:limestone"}, {["x"] = 2, ["y"] = 0, ["z"] = 15, ["name"] = "nodes_nature:limestone"}, {["x"] = 2, ["y"] = 0, ["z"] = 16, ["name"] = "nodes_nature:limestone"}, {["x"] = 2, ["y"] = 0, ["z"] = 17, ["name"] = "nodes_nature:limestone"}, {["x"] = 2, ["y"] = 0, ["z"] = 18, ["name"] = "nodes_nature:limestone"}, {["x"] = 2, ["y"] = 1, ["z"] = 0, ["name"] = "nodes_nature:limestone"}, {["x"] = 2, ["y"] = 1, ["z"] = 1, ["name"] = "nodes_nature:limestone"}, {["x"] = 2, ["y"] = 1, ["z"] = 2, ["name"] = "nodes_nature:limestone"}, {["x"] = 2, ["y"] = 1, ["z"] = 3, ["name"] = "nodes_nature:limestone"}, {["x"] = 2, ["y"] = 1, ["z"] = 4, ["name"] = "nodes_nature:limestone"}, {["x"] = 2, ["y"] = 1, ["z"] = 5, ["name"] = "nodes_nature:limestone"}, {["x"] = 2, ["y"] = 1, ["z"] = 6, ["name"] = "nodes_nature:limestone"}, {["x"] = 2, ["y"] = 1, ["z"] = 7, ["name"] = "nodes_nature:limestone"}, {["x"] = 2, ["y"] = 1, ["z"] = 8, ["name"] = "nodes_nature:limestone"}, {["x"] = 2, ["y"] = 1, ["z"] = 9, ["name"] = "nodes_nature:limestone"}, {["x"] = 2, ["y"] = 1, ["z"] = 10, ["name"] = "nodes_nature:limestone"}, {["x"] = 2, ["y"] = 1, ["z"] = 11, ["name"] = "nodes_nature:limestone"}, {["x"] = 2, ["y"] = 1, ["z"] = 12, ["name"] = "nodes_nature:limestone"}, {["x"] = 2, ["y"] = 1, ["z"] = 13, ["name"] = "nodes_nature:limestone"}, {["x"] = 2, ["y"] = 1, ["z"] = 14, ["name"] = "nodes_nature:limestone"}, {["x"] = 2, ["y"] = 1, ["z"] = 15, ["name"] = "nodes_nature:sand_wet_salty"}, {["x"] = 2, ["y"] = 1, ["z"] = 16, ["name"] = "nodes_nature:sand_wet_salty"}, {["x"] = 2, ["y"] = 1, ["z"] = 17, ["name"] = "nodes_nature:sand_wet_salty"}, {["x"] = 2, ["y"] = 1, ["z"] = 18, ["name"] = "nodes_nature:sand_wet_salty"}, {["x"] = 2, ["y"] = 2, ["z"] = 0, ["name"] = "nodes_nature:limestone"}, {["x"] = 2, ["y"] = 2, ["z"] = 1, ["name"] = "nodes_nature:limestone"}, {["x"] = 2, ["y"] = 2, ["z"] = 2, ["name"] = "nodes_nature:limestone"}, {["x"] = 2, ["y"] = 2, ["z"] = 3, ["name"] = "nodes_nature:limestone"}, {["x"] = 2, ["y"] = 2, ["z"] = 4, ["name"] = "nodes_nature:limestone"}, {["x"] = 2, ["y"] = 2, ["z"] = 5, ["name"] = "nodes_nature:limestone"}, {["x"] = 2, ["y"] = 2, ["z"] = 6, ["name"] = "nodes_nature:limestone"}, {["x"] = 2, ["y"] = 2, ["z"] = 7, ["name"] = "nodes_nature:limestone"}, {["x"] = 2, ["y"] = 2, ["z"] = 8, ["name"] = "nodes_nature:limestone"}, {["x"] = 2, ["y"] = 2, ["z"] = 9, ["name"] = "nodes_nature:limestone"}, {["x"] = 2, ["y"] = 2, ["z"] = 10, ["name"] = "nodes_nature:limestone"}, {["x"] = 2, ["y"] = 2, ["z"] = 11, ["name"] = "nodes_nature:sand_wet_salty"}, {["x"] = 2, ["y"] = 2, ["z"] = 12, ["name"] = "nodes_nature:sand_wet_salty"}, {["x"] = 2, ["y"] = 2, ["z"] = 13, ["name"] = "nodes_nature:sand_wet_salty"}, {["x"] = 2, ["y"] = 2, ["z"] = 14, ["name"] = "nodes_nature:sand_wet_salty"}, {["x"] = 2, ["y"] = 2, ["z"] = 15, ["name"] = "nodes_nature:sand_wet_salty"}, {["x"] = 2, ["y"] = 2, ["z"] = 16, ["name"] = "nodes_nature:sand_wet_salty"}, {["x"] = 2, ["y"] = 2, ["z"] = 17, ["name"] = "nodes_nature:sand_wet_salty"}, {["x"] = 2, ["y"] = 2, ["z"] = 18, ["name"] = "nodes_nature:sand_wet_salty"}, {["x"] = 2, ["y"] = 3, ["z"] = 0, ["name"] = "nodes_nature:limestone"}, {["x"] = 2, ["y"] = 3, ["z"] = 1, ["name"] = "nodes_nature:limestone"}, {["x"] = 2, ["y"] = 3, ["z"] = 2, ["name"] = "nodes_nature:limestone"}, {["x"] = 2, ["y"] = 3, ["z"] = 3, ["name"] = "nodes_nature:limestone"}, {["x"] = 2, ["y"] = 3, ["z"] = 4, ["name"] = "nodes_nature:limestone"}, {["x"] = 2, ["y"] = 3, ["z"] = 5, ["name"] = "nodes_nature:limestone"}, {["x"] = 2, ["y"] = 3, ["z"] = 6, ["name"] = "nodes_nature:limestone"}, {["x"] = 2, ["y"] = 3, ["z"] = 7, ["name"] = "nodes_nature:limestone"}, {["x"] = 2, ["y"] = 3, ["z"] = 8, ["name"] = "nodes_nature:sand_wet_salty"}, {["x"] = 2, ["y"] = 3, ["z"] = 9, ["name"] = "nodes_nature:sand_wet_salty"}, {["x"] = 2, ["y"] = 3, ["z"] = 10, ["name"] = "nodes_nature:sand_wet_salty"}, {["x"] = 2, ["y"] = 3, ["z"] = 11, ["name"] = "nodes_nature:sand_wet_salty"}, {["x"] = 2, ["y"] = 3, ["z"] = 12, ["name"] = "nodes_nature:sand_wet_salty"}, {["x"] = 2, ["y"] = 3, ["z"] = 13, ["name"] = "nodes_nature:sand_wet_salty"}, {["x"] = 2, ["y"] = 3, ["z"] = 14, ["name"] = "nodes_nature:sand_wet_salty"}, {["x"] = 2, ["y"] = 3, ["z"] = 15, ["name"] = "nodes_nature:sand_wet_salty"}, {["x"] = 2, ["y"] = 3, ["z"] = 16, ["name"] = "nodes_nature:sand_wet_salty"}, {["x"] = 2, ["y"] = 3, ["z"] = 17, ["name"] = "nodes_nature:sand_wet_salty"}, {["x"] = 2, ["y"] = 3, ["z"] = 18, ["name"] = "nodes_nature:sand_wet_salty"}, {["x"] = 2, ["y"] = 4, ["z"] = 0, ["name"] = "nodes_nature:limestone"}, {["x"] = 2, ["y"] = 4, ["z"] = 1, ["name"] = "nodes_nature:limestone"}, {["x"] = 2, ["y"] = 4, ["z"] = 2, ["name"] = "nodes_nature:limestone"}, {["x"] = 2, ["y"] = 4, ["z"] = 3, ["name"] = "nodes_nature:limestone"}, {["x"] = 2, ["y"] = 4, ["z"] = 4, ["name"] = "nodes_nature:limestone"}, {["x"] = 2, ["y"] = 4, ["z"] = 5, ["name"] = "nodes_nature:sand_wet_salty"}, {["x"] = 2, ["y"] = 4, ["z"] = 6, ["name"] = "nodes_nature:sand_wet_salty"}, {["x"] = 2, ["y"] = 4, ["z"] = 7, ["name"] = "nodes_nature:sand_wet_salty"}, {["x"] = 2, ["y"] = 4, ["z"] = 8, ["name"] = "nodes_nature:sand_wet_salty"}, {["x"] = 2, ["y"] = 4, ["z"] = 9, ["name"] = "nodes_nature:sand_wet_salty"}, {["x"] = 2, ["y"] = 4, ["z"] = 10, ["name"] = "nodes_nature:sand_wet_salty"}, {["x"] = 2, ["y"] = 4, ["z"] = 11, ["name"] = "nodes_nature:sand_wet_salty"}, {["x"] = 2, ["y"] = 4, ["z"] = 12, ["name"] = "nodes_nature:sand_wet_salty"}, {["x"] = 2, ["y"] = 4, ["z"] = 13, ["name"] = "nodes_nature:sand_wet_salty"}, {["x"] = 2, ["y"] = 4, ["z"] = 14, ["name"] = "nodes_nature:sand_wet_salty"}, {["x"] = 2, ["y"] = 4, ["param1"] = 174, ["z"] = 15, ["name"] = "nodes_nature:salt_water_source"}, {["x"] = 2, ["meta"] = {["fields"] = {["infotext"] = "\27(T@tech)Clear Glass Window\27E\
Owned by singleplayer", ["owner"] = "singleplayer"}, ["inventory"] = {}}, ["param2"] = 2, ["y"] = 4, ["param1"] = 191, ["z"] = 16, ["name"] = "tech:window_clear"}, {["x"] = 2, ["y"] = 4, ["param1"] = 206, ["z"] = 17, ["name"] = "nodes_nature:salt_water_source"}, {["x"] = 2, ["y"] = 4, ["param1"] = 189, ["z"] = 18, ["name"] = "nodes_nature:salt_water_source"}, {["x"] = 2, ["y"] = 5, ["z"] = 0, ["name"] = "nodes_nature:limestone"}, {["x"] = 2, ["y"] = 5, ["z"] = 1, ["name"] = "nodes_nature:limestone"}, {["x"] = 2, ["y"] = 5, ["z"] = 2, ["name"] = "nodes_nature:limestone"}, {["x"] = 2, ["y"] = 5, ["z"] = 3, ["name"] = "nodes_nature:sand_wet_salty"}, {["x"] = 2, ["y"] = 5, ["z"] = 4, ["name"] = "nodes_nature:sand_wet_salty"}, {["x"] = 2, ["y"] = 5, ["z"] = 5, ["name"] = "nodes_nature:sand_wet_salty"}, {["x"] = 2, ["y"] = 5, ["z"] = 6, ["name"] = "nodes_nature:sand_wet_salty"}, {["x"] = 2, ["y"] = 5, ["z"] = 7, ["name"] = "nodes_nature:sand_wet_salty"}, {["x"] = 2, ["y"] = 5, ["z"] = 8, ["name"] = "nodes_nature:sand_wet_salty"}, {["x"] = 2, ["y"] = 5, ["z"] = 9, ["name"] = "nodes_nature:sand_wet_salty"}, {["x"] = 2, ["y"] = 5, ["z"] = 10, ["name"] = "nodes_nature:sand_wet_salty"}, {["x"] = 2, ["y"] = 5, ["param1"] = 125, ["z"] = 11, ["name"] = "nodes_nature:salt_water_source"}, {["x"] = 2, ["y"] = 5, ["param1"] = 141, ["z"] = 12, ["name"] = "nodes_nature:salt_water_source"}, {["x"] = 2, ["y"] = 5, ["param1"] = 158, ["z"] = 13, ["name"] = "nodes_nature:salt_water_source"}, {["x"] = 2, ["y"] = 5, ["param1"] = 174, ["z"] = 14, ["name"] = "nodes_nature:salt_water_source"}, {["x"] = 2, ["y"] = 5, ["param1"] = 190, ["z"] = 15, ["name"] = "nodes_nature:salt_water_source"}, {["x"] = 2, ["meta"] = {["fields"] = {["infotext"] = "\27(T@tech)Clear Glass Window\27E\
Owned by singleplayer", ["owner"] = "singleplayer"}, ["inventory"] = {}}, ["y"] = 5, ["param1"] = 207, ["z"] = 16, ["name"] = "tech:window_clear"}, {["x"] = 2, ["meta"] = {["fields"] = {["infotext"] = "Sun Stone\
Owned by singleplayer", ["owner"] = "singleplayer"}, ["inventory"] = {}}, ["param2"] = 5, ["y"] = 5, ["param1"] = 222, ["z"] = 17, ["name"] = "artifacts:sun_stone"}, {["x"] = 2, ["y"] = 5, ["param1"] = 205, ["z"] = 18, ["name"] = "nodes_nature:salt_water_source"}, {["x"] = 2, ["y"] = 6, ["z"] = 0, ["name"] = "nodes_nature:limestone"}, {["x"] = 2, ["y"] = 6, ["z"] = 1, ["name"] = "nodes_nature:sand_wet_salty"}, {["x"] = 2, ["y"] = 6, ["z"] = 2, ["name"] = "nodes_nature:sand_wet_salty"}, {["x"] = 2, ["y"] = 6, ["z"] = 3, ["name"] = "nodes_nature:sand_wet_salty"}, {["x"] = 2, ["y"] = 6, ["z"] = 4, ["name"] = "nodes_nature:sand_wet_salty"}, {["x"] = 2, ["y"] = 6, ["z"] = 5, ["name"] = "nodes_nature:sand_wet_salty"}, {["x"] = 2, ["y"] = 6, ["z"] = 6, ["name"] = "nodes_nature:sand_wet_salty"}, {["x"] = 2, ["y"] = 6, ["z"] = 7, ["name"] = "nodes_nature:sand_wet_salty"}, {["x"] = 2, ["y"] = 6, ["param1"] = 141, ["z"] = 8, ["name"] = "nodes_nature:salt_water_source"}, {["x"] = 2, ["y"] = 6, ["param1"] = 158, ["z"] = 9, ["name"] = "nodes_nature:salt_water_source"}, {["x"] = 2, ["y"] = 6, ["param1"] = 142, ["z"] = 10, ["name"] = "nodes_nature:salt_water_source"}, {["x"] = 2, ["y"] = 6, ["param1"] = 126, ["z"] = 11, ["name"] = "nodes_nature:salt_water_source"}, {["x"] = 2, ["y"] = 6, ["param1"] = 142, ["z"] = 12, ["name"] = "nodes_nature:salt_water_source"}, {["x"] = 2, ["y"] = 6, ["param1"] = 158, ["z"] = 13, ["name"] = "nodes_nature:salt_water_source"}, {["x"] = 2, ["y"] = 6, ["param1"] = 158, ["z"] = 14, ["name"] = "nodes_nature:salt_water_source"}, {["x"] = 2, ["y"] = 6, ["param1"] = 174, ["z"] = 15, ["name"] = "nodes_nature:salt_water_source"}, {["x"] = 2, ["meta"] = {["fields"] = {["infotext"] = "\27(T@tech)Clear Glass Window\27E\
Owned by singleplayer", ["owner"] = "singleplayer"}, ["inventory"] = {}}, ["y"] = 6, ["param1"] = 191, ["z"] = 16, ["name"] = "tech:window_clear"}, {["x"] = 2, ["y"] = 6, ["param1"] = 206, ["z"] = 17, ["name"] = "nodes_nature:salt_water_source"}, {["x"] = 2, ["y"] = 6, ["param1"] = 189, ["z"] = 18, ["name"] = "nodes_nature:salt_water_source"}, {["x"] = 2, ["y"] = 7, ["z"] = 0, ["name"] = "nodes_nature:sand_wet_salty"}, {["x"] = 2, ["y"] = 7, ["z"] = 1, ["name"] = "nodes_nature:sand_wet_salty"}, {["x"] = 2, ["y"] = 7, ["z"] = 2, ["name"] = "nodes_nature:sand_wet_salty"}, {["x"] = 2, ["y"] = 7, ["z"] = 3, ["name"] = "nodes_nature:sand_wet_salty"}, {["x"] = 2, ["y"] = 7, ["z"] = 4, ["name"] = "nodes_nature:sand_wet_salty"}, {["x"] = 2, ["y"] = 7, ["param1"] = 141, ["z"] = 5, ["name"] = "nodes_nature:salt_water_source"}, {["x"] = 2, ["y"] = 7, ["param1"] = 158, ["z"] = 6, ["name"] = "nodes_nature:salt_water_source"}, {["x"] = 2, ["y"] = 7, ["param1"] = 142, ["z"] = 7, ["name"] = "nodes_nature:salt_water_source"}, {["x"] = 2, ["y"] = 7, ["param1"] = 158, ["z"] = 8, ["name"] = "nodes_nature:salt_water_source"}, {["x"] = 2, ["y"] = 7, ["param1"] = 174, ["z"] = 9, ["name"] = "nodes_nature:salt_water_source"}, {["x"] = 2, ["y"] = 7, ["param1"] = 158, ["z"] = 10, ["name"] = "nodes_nature:salt_water_source"}, {["x"] = 2, ["y"] = 7, ["param1"] = 142, ["z"] = 11, ["name"] = "nodes_nature:salt_water_source"}, {["x"] = 2, ["y"] = 7, ["param1"] = 158, ["z"] = 12, ["name"] = "nodes_nature:salt_water_source"}, {["x"] = 2, ["y"] = 7, ["param1"] = 174, ["z"] = 13, ["name"] = "nodes_nature:salt_water_source"}, {["x"] = 2, ["y"] = 7, ["param1"] = 158, ["z"] = 14, ["name"] = "nodes_nature:salt_water_source"}, {["x"] = 2, ["y"] = 7, ["param1"] = 158, ["z"] = 15, ["name"] = "nodes_nature:salt_water_source"}, {["x"] = 2, ["meta"] = {["fields"] = {["infotext"] = "\27(T@tech)Clear Glass Window\27E\
Owned by singleplayer", ["owner"] = "singleplayer"}, ["inventory"] = {}}, ["y"] = 7, ["param1"] = 175, ["z"] = 16, ["name"] = "tech:window_clear"}, {["x"] = 2, ["y"] = 7, ["param1"] = 190, ["z"] = 17, ["name"] = "nodes_nature:salt_water_source"}, {["x"] = 2, ["y"] = 7, ["param1"] = 173, ["z"] = 18, ["name"] = "nodes_nature:salt_water_source"}, {["x"] = 2, ["y"] = 8, ["z"] = 0, ["name"] = "nodes_nature:sand_wet_salty"}, {["x"] = 2, ["y"] = 8, ["z"] = 1, ["name"] = "nodes_nature:sand_wet_salty"}, {["x"] = 2, ["y"] = 8, ["z"] = 2, ["name"] = "nodes_nature:sand_wet_salty"}, {["x"] = 2, ["y"] = 8, ["param1"] = 125, ["z"] = 3, ["name"] = "nodes_nature:salt_water_source"}, {["x"] = 2, ["y"] = 8, ["param1"] = 142, ["z"] = 4, ["name"] = "nodes_nature:salt_water_source"}, {["x"] = 2, ["y"] = 8, ["param1"] = 158, ["z"] = 5, ["name"] = "nodes_nature:salt_water_source"}, {["x"] = 2, ["y"] = 8, ["param1"] = 174, ["z"] = 6, ["name"] = "nodes_nature:salt_water_source"}, {["x"] = 2, ["y"] = 8, ["param1"] = 158, ["z"] = 7, ["name"] = "nodes_nature:salt_water_source"}, {["x"] = 2, ["y"] = 8, ["param1"] = 174, ["z"] = 8, ["name"] = "nodes_nature:salt_water_source"}, {["x"] = 2, ["y"] = 8, ["param1"] = 190, ["z"] = 9, ["name"] = "nodes_nature:salt_water_source"}, {["x"] = 2, ["y"] = 8, ["param1"] = 174, ["z"] = 10, ["name"] = "nodes_nature:salt_water_source"}, {["x"] = 2, ["y"] = 8, ["param1"] = 158, ["z"] = 11, ["name"] = "nodes_nature:salt_water_source"}, {["x"] = 2, ["y"] = 8, ["param1"] = 174, ["z"] = 12, ["name"] = "nodes_nature:salt_water_source"}, {["x"] = 2, ["y"] = 8, ["param1"] = 190, ["z"] = 13, ["name"] = "nodes_nature:salt_water_source"}, {["x"] = 2, ["y"] = 8, ["param1"] = 174, ["z"] = 14, ["name"] = "nodes_nature:salt_water_source"}, {["x"] = 2, ["y"] = 8, ["param1"] = 158, ["z"] = 15, ["name"] = "nodes_nature:salt_water_source"}, {["x"] = 2, ["meta"] = {["fields"] = {["infotext"] = "\27(T@tech)Clear Glass Window\27E\
Owned by singleplayer", ["owner"] = "singleplayer"}, ["inventory"] = {}}, ["y"] = 8, ["param1"] = 159, ["z"] = 16, ["name"] = "tech:window_clear"}, {["x"] = 2, ["y"] = 8, ["param1"] = 174, ["z"] = 17, ["name"] = "nodes_nature:salt_water_source"}, {["x"] = 2, ["y"] = 8, ["param1"] = 157, ["z"] = 18, ["name"] = "nodes_nature:salt_water_source"}, {["x"] = 2, ["y"] = 9, ["z"] = 0, ["name"] = "nodes_nature:basalt"}, {["x"] = 2, ["meta"] = {["fields"] = {["owner"] = "singleplayer", ["infotext"] = "\27(T@tech)Clear Glass Window\27E\
Owned by singleplayer"}, ["inventory"] = {}}, ["y"] = 9, ["param1"] = 175, ["z"] = 1, ["name"] = "tech:window_clear"}, {["x"] = 2, ["y"] = 9, ["param1"] = 158, ["z"] = 2, ["name"] = "nodes_nature:salt_water_source"}, {["x"] = 2, ["y"] = 9, ["param1"] = 142, ["z"] = 3, ["name"] = "nodes_nature:salt_water_source"}, {["x"] = 2, ["y"] = 9, ["param1"] = 158, ["z"] = 4, ["name"] = "nodes_nature:salt_water_source"}, {["x"] = 2, ["y"] = 9, ["param1"] = 174, ["z"] = 5, ["name"] = "nodes_nature:salt_water_source"}, {["x"] = 2, ["y"] = 9, ["param1"] = 190, ["z"] = 6, ["name"] = "nodes_nature:salt_water_source"}, {["x"] = 2, ["y"] = 9, ["param1"] = 174, ["z"] = 7, ["name"] = "nodes_nature:salt_water_source"}, {["x"] = 2, ["y"] = 9, ["param1"] = 158, ["z"] = 8, ["name"] = "nodes_nature:salt_water_source"}, {["x"] = 2, ["y"] = 9, ["param1"] = 174, ["z"] = 9, ["name"] = "nodes_nature:salt_water_source"}, {["x"] = 2, ["y"] = 9, ["param1"] = 158, ["z"] = 10, ["name"] = "nodes_nature:salt_water_source"}, {["x"] = 2, ["y"] = 9, ["param1"] = 142, ["z"] = 11, ["name"] = "nodes_nature:salt_water_source"}, {["x"] = 2, ["y"] = 9, ["param1"] = 158, ["z"] = 12, ["name"] = "nodes_nature:salt_water_source"}, {["x"] = 2, ["y"] = 9, ["param1"] = 174, ["z"] = 13, ["name"] = "nodes_nature:salt_water_source"}, {["x"] = 2, ["y"] = 9, ["param1"] = 158, ["z"] = 14, ["name"] = "nodes_nature:salt_water_source"}, {["x"] = 2, ["y"] = 9, ["param1"] = 142, ["z"] = 15, ["name"] = "nodes_nature:salt_water_source"}, {["x"] = 2, ["meta"] = {["fields"] = {["infotext"] = "\27(T@tech)Clear Glass Window\27E\
Owned by singleplayer", ["owner"] = "singleplayer"}, ["inventory"] = {}}, ["y"] = 9, ["param1"] = 159, ["z"] = 16, ["name"] = "tech:window_clear"}, {["x"] = 2, ["y"] = 9, ["param1"] = 158, ["z"] = 17, ["name"] = "nodes_nature:salt_water_source"}, {["x"] = 2, ["y"] = 9, ["param1"] = 141, ["z"] = 18, ["name"] = "nodes_nature:salt_water_source"}, {["x"] = 2, ["y"] = 10, ["param1"] = 206, ["z"] = 0, ["name"] = "nodes_nature:salt_water_source"}, {["x"] = 2, ["meta"] = {["fields"] = {["owner"] = "singleplayer", ["infotext"] = "\27(T@tech)Clear Glass Window\27E\
Owned by singleplayer"}, ["inventory"] = {}}, ["y"] = 10, ["param1"] = 191, ["z"] = 1, ["name"] = "tech:window_clear"}, {["x"] = 2, ["y"] = 10, ["param1"] = 174, ["z"] = 2, ["name"] = "nodes_nature:salt_water_source"}, {["x"] = 2, ["y"] = 10, ["param1"] = 158, ["z"] = 3, ["name"] = "nodes_nature:salt_water_source"}, {["x"] = 2, ["y"] = 10, ["param1"] = 142, ["z"] = 4, ["name"] = "nodes_nature:salt_water_source"}, {["x"] = 2, ["y"] = 10, ["param1"] = 158, ["z"] = 5, ["name"] = "nodes_nature:salt_water_source"}, {["x"] = 2, ["y"] = 10, ["param1"] = 174, ["z"] = 6, ["name"] = "nodes_nature:salt_water_source"}, {["x"] = 2, ["y"] = 10, ["param1"] = 158, ["z"] = 7, ["name"] = "nodes_nature:salt_water_source"}, {["x"] = 2, ["y"] = 10, ["param1"] = 142, ["z"] = 8, ["name"] = "nodes_nature:salt_water_source"}, {["x"] = 2, ["y"] = 10, ["param1"] = 158, ["z"] = 9, ["name"] = "nodes_nature:salt_water_source"}, {["x"] = 2, ["y"] = 10, ["param1"] = 142, ["z"] = 10, ["name"] = "nodes_nature:salt_water_source"}, {["x"] = 2, ["y"] = 10, ["param1"] = 126, ["z"] = 11, ["name"] = "nodes_nature:salt_water_source"}, {["x"] = 2, ["y"] = 10, ["param1"] = 142, ["z"] = 12, ["name"] = "nodes_nature:salt_water_source"}, {["x"] = 2, ["y"] = 10, ["param1"] = 158, ["z"] = 13, ["name"] = "nodes_nature:salt_water_source"}, {["x"] = 2, ["y"] = 10, ["param1"] = 142, ["z"] = 14, ["name"] = "nodes_nature:salt_water_source"}, {["x"] = 2, ["y"] = 10, ["param1"] = 158, ["z"] = 15, ["name"] = "nodes_nature:salt_water_source"}, {["x"] = 2, ["meta"] = {["fields"] = {["infotext"] = "\27(T@tech)Clear Glass Window\27E\
Owned by singleplayer", ["owner"] = "singleplayer"}, ["inventory"] = {}}, ["y"] = 10, ["param1"] = 175, ["z"] = 16, ["name"] = "tech:window_clear"}, {["x"] = 2, ["y"] = 10, ["param1"] = 158, ["z"] = 17, ["name"] = "nodes_nature:salt_water_source"}, {["x"] = 2, ["y"] = 10, ["param1"] = 142, ["z"] = 18, ["name"] = "nodes_nature:salt_water_source"}, {["x"] = 3, ["y"] = 0, ["z"] = 0, ["name"] = "nodes_nature:limestone"}, {["x"] = 3, ["y"] = 0, ["z"] = 1, ["name"] = "nodes_nature:limestone"}, {["x"] = 3, ["y"] = 0, ["z"] = 2, ["name"] = "nodes_nature:limestone"}, {["x"] = 3, ["y"] = 0, ["z"] = 3, ["name"] = "nodes_nature:limestone"}, {["x"] = 3, ["y"] = 0, ["z"] = 4, ["name"] = "nodes_nature:limestone"}, {["x"] = 3, ["y"] = 0, ["z"] = 5, ["name"] = "nodes_nature:limestone"}, {["x"] = 3, ["y"] = 0, ["z"] = 6, ["name"] = "nodes_nature:limestone"}, {["x"] = 3, ["y"] = 0, ["z"] = 7, ["name"] = "nodes_nature:limestone"}, {["x"] = 3, ["y"] = 0, ["z"] = 8, ["name"] = "nodes_nature:limestone"}, {["x"] = 3, ["y"] = 0, ["z"] = 9, ["name"] = "nodes_nature:limestone"}, {["x"] = 3, ["y"] = 0, ["z"] = 10, ["name"] = "nodes_nature:limestone"}, {["x"] = 3, ["y"] = 0, ["z"] = 11, ["name"] = "nodes_nature:limestone"}, {["x"] = 3, ["y"] = 0, ["z"] = 12, ["name"] = "nodes_nature:limestone"}, {["x"] = 3, ["y"] = 0, ["z"] = 13, ["name"] = "nodes_nature:limestone"}, {["x"] = 3, ["y"] = 0, ["z"] = 14, ["name"] = "nodes_nature:limestone"}, {["x"] = 3, ["y"] = 0, ["z"] = 15, ["name"] = "nodes_nature:limestone"}, {["x"] = 3, ["y"] = 0, ["z"] = 16, ["name"] = "nodes_nature:limestone"}, {["x"] = 3, ["y"] = 0, ["z"] = 17, ["name"] = "nodes_nature:limestone"}, {["x"] = 3, ["y"] = 0, ["z"] = 18, ["name"] = "nodes_nature:sand_wet_salty"}, {["x"] = 3, ["y"] = 1, ["z"] = 0, ["name"] = "nodes_nature:limestone"}, {["x"] = 3, ["y"] = 1, ["z"] = 1, ["name"] = "nodes_nature:limestone"}, {["x"] = 3, ["y"] = 1, ["z"] = 2, ["name"] = "nodes_nature:limestone"}, {["x"] = 3, ["y"] = 1, ["z"] = 3, ["name"] = "nodes_nature:limestone"}, {["x"] = 3, ["y"] = 1, ["z"] = 4, ["name"] = "nodes_nature:limestone"}, {["x"] = 3, ["y"] = 1, ["z"] = 5, ["name"] = "nodes_nature:limestone"}, {["x"] = 3, ["y"] = 1, ["z"] = 6, ["name"] = "nodes_nature:limestone"}, {["x"] = 3, ["y"] = 1, ["z"] = 7, ["name"] = "nodes_nature:limestone"}, {["x"] = 3, ["y"] = 1, ["z"] = 8, ["name"] = "nodes_nature:limestone"}, {["x"] = 3, ["y"] = 1, ["z"] = 9, ["name"] = "nodes_nature:limestone"}, {["x"] = 3, ["y"] = 1, ["z"] = 10, ["name"] = "nodes_nature:limestone"}, {["x"] = 3, ["y"] = 1, ["z"] = 11, ["name"] = "nodes_nature:limestone"}, {["x"] = 3, ["y"] = 1, ["z"] = 12, ["name"] = "nodes_nature:limestone"}, {["x"] = 3, ["y"] = 1, ["z"] = 13, ["name"] = "nodes_nature:limestone"}, {["x"] = 3, ["y"] = 1, ["z"] = 14, ["name"] = "nodes_nature:sand_wet_salty"}, {["x"] = 3, ["y"] = 1, ["z"] = 15, ["name"] = "nodes_nature:sand_wet_salty"}, {["x"] = 3, ["y"] = 1, ["z"] = 16, ["name"] = "nodes_nature:sand_wet_salty"}, {["x"] = 3, ["y"] = 1, ["z"] = 17, ["name"] = "nodes_nature:sand_wet_salty"}, {["x"] = 3, ["y"] = 1, ["z"] = 18, ["name"] = "nodes_nature:sand_wet_salty"}, {["x"] = 3, ["y"] = 2, ["z"] = 0, ["name"] = "nodes_nature:limestone"}, {["x"] = 3, ["y"] = 2, ["z"] = 1, ["name"] = "nodes_nature:limestone"}, {["x"] = 3, ["y"] = 2, ["z"] = 2, ["name"] = "nodes_nature:limestone"}, {["x"] = 3, ["y"] = 2, ["z"] = 3, ["name"] = "nodes_nature:limestone"}, {["x"] = 3, ["y"] = 2, ["z"] = 4, ["name"] = "nodes_nature:limestone"}, {["x"] = 3, ["y"] = 2, ["z"] = 5, ["name"] = "nodes_nature:limestone"}, {["x"] = 3, ["y"] = 2, ["z"] = 6, ["name"] = "nodes_nature:limestone"}, {["x"] = 3, ["y"] = 2, ["z"] = 7, ["name"] = "nodes_nature:limestone"}, {["x"] = 3, ["y"] = 2, ["z"] = 8, ["name"] = "nodes_nature:limestone"}, {["x"] = 3, ["y"] = 2, ["z"] = 9, ["name"] = "nodes_nature:limestone"}, {["x"] = 3, ["y"] = 2, ["z"] = 10, ["name"] = "nodes_nature:sand_wet_salty"}, {["x"] = 3, ["y"] = 2, ["z"] = 11, ["name"] = "nodes_nature:sand_wet_salty"}, {["x"] = 3, ["y"] = 2, ["z"] = 12, ["name"] = "nodes_nature:sand_wet_salty"}, {["x"] = 3, ["y"] = 2, ["z"] = 13, ["name"] = "nodes_nature:sand_wet_salty"}, {["x"] = 3, ["y"] = 2, ["z"] = 14, ["name"] = "nodes_nature:sand_wet_salty"}, {["x"] = 3, ["y"] = 2, ["z"] = 15, ["name"] = "nodes_nature:sand_wet_salty"}, {["x"] = 3, ["y"] = 2, ["z"] = 16, ["name"] = "nodes_nature:sand_wet_salty"}, {["x"] = 3, ["y"] = 2, ["z"] = 17, ["name"] = "nodes_nature:sand_wet_salty"}, {["x"] = 3, ["y"] = 2, ["z"] = 18, ["name"] = "nodes_nature:sand_wet_salty"}, {["x"] = 3, ["y"] = 3, ["z"] = 0, ["name"] = "nodes_nature:limestone"}, {["x"] = 3, ["y"] = 3, ["z"] = 1, ["name"] = "nodes_nature:limestone"}, {["x"] = 3, ["y"] = 3, ["z"] = 2, ["name"] = "nodes_nature:limestone"}, {["x"] = 3, ["y"] = 3, ["z"] = 3, ["name"] = "nodes_nature:limestone"}, {["x"] = 3, ["y"] = 3, ["z"] = 4, ["name"] = "nodes_nature:limestone"}, {["x"] = 3, ["y"] = 3, ["z"] = 5, ["name"] = "nodes_nature:limestone"}, {["x"] = 3, ["y"] = 3, ["z"] = 6, ["name"] = "nodes_nature:limestone"}, {["x"] = 3, ["y"] = 3, ["z"] = 7, ["name"] = "nodes_nature:sand_wet_salty"}, {["x"] = 3, ["y"] = 3, ["z"] = 8, ["name"] = "nodes_nature:sand_wet_salty"}, {["x"] = 3, ["y"] = 3, ["z"] = 9, ["name"] = "nodes_nature:sand_wet_salty"}, {["x"] = 3, ["y"] = 3, ["z"] = 10, ["name"] = "nodes_nature:sand_wet_salty"}, {["x"] = 3, ["y"] = 3, ["z"] = 11, ["name"] = "nodes_nature:sand_wet_salty"}, {["x"] = 3, ["y"] = 3, ["z"] = 12, ["name"] = "nodes_nature:sand_wet_salty"}, {["x"] = 3, ["y"] = 3, ["z"] = 13, ["name"] = "nodes_nature:sand_wet_salty"}, {["x"] = 3, ["y"] = 3, ["z"] = 14, ["name"] = "nodes_nature:sand_wet_salty"}, {["x"] = 3, ["y"] = 3, ["z"] = 15, ["name"] = "nodes_nature:sand_wet_salty"}, {["x"] = 3, ["y"] = 3, ["z"] = 16, ["name"] = "nodes_nature:sand_wet_salty"}, {["x"] = 3, ["y"] = 3, ["z"] = 17, ["name"] = "nodes_nature:sand_wet_salty"}, {["x"] = 3, ["y"] = 3, ["param1"] = 156, ["z"] = 18, ["name"] = "nodes_nature:salt_water_source"}, {["x"] = 3, ["y"] = 4, ["z"] = 0, ["name"] = "nodes_nature:limestone"}, {["x"] = 3, ["y"] = 4, ["z"] = 1, ["name"] = "nodes_nature:limestone"}, {["x"] = 3, ["y"] = 4, ["z"] = 2, ["name"] = "nodes_nature:limestone"}, {["x"] = 3, ["y"] = 4, ["z"] = 3, ["name"] = "nodes_nature:limestone"}, {["x"] = 3, ["y"] = 4, ["z"] = 4, ["name"] = "nodes_nature:limestone"}, {["x"] = 3, ["y"] = 4, ["z"] = 5, ["name"] = "nodes_nature:sand_wet_salty"}, {["x"] = 3, ["y"] = 4, ["z"] = 6, ["name"] = "nodes_nature:sand_wet_salty"}, {["x"] = 3, ["y"] = 4, ["z"] = 7, ["name"] = "nodes_nature:sand_wet_salty"}, {["x"] = 3, ["y"] = 4, ["z"] = 8, ["name"] = "nodes_nature:sand_wet_salty"}, {["x"] = 3, ["y"] = 4, ["z"] = 9, ["name"] = "nodes_nature:sand_wet_salty"}, {["x"] = 3, ["y"] = 4, ["z"] = 10, ["name"] = "nodes_nature:sand_wet_salty"}, {["x"] = 3, ["y"] = 4, ["z"] = 11, ["name"] = "nodes_nature:sand_wet_salty"}, {["x"] = 3, ["y"] = 4, ["z"] = 12, ["name"] = "nodes_nature:sand_wet_salty"}, {["x"] = 3, ["y"] = 4, ["z"] = 13, ["name"] = "nodes_nature:sand_wet_salty"}, {["x"] = 3, ["y"] = 4, ["param1"] = 141, ["z"] = 14, ["name"] = "nodes_nature:salt_water_source"}, {["x"] = 3, ["y"] = 4, ["param1"] = 158, ["z"] = 15, ["name"] = "nodes_nature:salt_water_source"}, {["x"] = 3, ["meta"] = {["fields"] = {["infotext"] = "\27(T@tech)Clear Glass Window\27E\
Owned by singleplayer", ["owner"] = "singleplayer"}, ["inventory"] = {}}, ["param2"] = 2, ["y"] = 4, ["param1"] = 175, ["z"] = 16, ["name"] = "tech:window_clear"}, {["x"] = 3, ["y"] = 4, ["param1"] = 190, ["z"] = 17, ["name"] = "nodes_nature:salt_water_source"}, {["x"] = 3, ["y"] = 4, ["param1"] = 173, ["z"] = 18, ["name"] = "nodes_nature:salt_water_source"}, {["x"] = 3, ["y"] = 5, ["z"] = 0, ["name"] = "nodes_nature:limestone"}, {["x"] = 3, ["y"] = 5, ["z"] = 1, ["name"] = "nodes_nature:limestone"}, {["x"] = 3, ["y"] = 5, ["z"] = 2, ["name"] = "nodes_nature:limestone"}, {["x"] = 3, ["y"] = 5, ["z"] = 3, ["name"] = "nodes_nature:sand_wet_salty"}, {["x"] = 3, ["y"] = 5, ["z"] = 4, ["name"] = "nodes_nature:sand_wet_salty"}, {["x"] = 3, ["y"] = 5, ["z"] = 5, ["name"] = "nodes_nature:sand_wet_salty"}, {["x"] = 3, ["y"] = 5, ["z"] = 6, ["name"] = "nodes_nature:sand_wet_salty"}, {["x"] = 3, ["y"] = 5, ["z"] = 7, ["name"] = "nodes_nature:sand_wet_salty"}, {["x"] = 3, ["y"] = 5, ["z"] = 8, ["name"] = "nodes_nature:sand_wet_salty"}, {["x"] = 3, ["y"] = 5, ["z"] = 9, ["name"] = "nodes_nature:sand_wet_salty"}, {["x"] = 3, ["y"] = 5, ["param1"] = 108, ["z"] = 10, ["name"] = "nodes_nature:salt_water_source"}, {["x"] = 3, ["y"] = 5, ["param1"] = 108, ["z"] = 11, ["name"] = "nodes_nature:salt_water_source"}, {["x"] = 3, ["y"] = 5, ["param1"] = 124, ["z"] = 12, ["name"] = "nodes_nature:salt_water_source"}, {["x"] = 3, ["y"] = 5, ["param1"] = 141, ["z"] = 13, ["name"] = "nodes_nature:salt_water_source"}, {["x"] = 3, ["y"] = 5, ["param1"] = 157, ["z"] = 14, ["name"] = "nodes_nature:salt_water_source"}, {["x"] = 3, ["y"] = 5, ["param1"] = 174, ["z"] = 15, ["name"] = "nodes_nature:salt_water_source"}, {["x"] = 3, ["meta"] = {["fields"] = {["infotext"] = "\27(T@tech)Clear Glass Window\27E\
Owned by singleplayer", ["owner"] = "singleplayer"}, ["inventory"] = {}}, ["y"] = 5, ["param1"] = 191, ["z"] = 16, ["name"] = "tech:window_clear"}, {["x"] = 3, ["y"] = 5, ["param1"] = 206, ["z"] = 17, ["name"] = "nodes_nature:salt_water_source"}, {["x"] = 3, ["y"] = 5, ["param1"] = 189, ["z"] = 18, ["name"] = "nodes_nature:salt_water_source"}, {["x"] = 3, ["y"] = 6, ["z"] = 0, ["name"] = "nodes_nature:sand_wet_salty"}, {["x"] = 3, ["y"] = 6, ["z"] = 1, ["name"] = "nodes_nature:sand_wet_salty"}, {["x"] = 3, ["y"] = 6, ["z"] = 2, ["name"] = "nodes_nature:sand_wet_salty"}, {["x"] = 3, ["y"] = 6, ["z"] = 3, ["name"] = "nodes_nature:sand_wet_salty"}, {["x"] = 3, ["y"] = 6, ["z"] = 4, ["name"] = "nodes_nature:sand_wet_salty"}, {["x"] = 3, ["y"] = 6, ["z"] = 5, ["name"] = "nodes_nature:sand_wet_salty"}, {["x"] = 3, ["y"] = 6, ["z"] = 6, ["name"] = "nodes_nature:sand_wet_salty"}, {["x"] = 3, ["y"] = 6, ["param1"] = 108, ["z"] = 7, ["name"] = "nodes_nature:salt_water_source"}, {["x"] = 3, ["y"] = 6, ["param1"] = 124, ["z"] = 8, ["name"] = "nodes_nature:salt_water_source"}, {["x"] = 3, ["y"] = 6, ["param1"] = 141, ["z"] = 9, ["name"] = "nodes_nature:salt_water_source"}, {["x"] = 3, ["y"] = 6, ["param1"] = 125, ["z"] = 10, ["name"] = "nodes_nature:salt_water_source"}, {["x"] = 3, ["y"] = 6, ["param1"] = 109, ["z"] = 11, ["name"] = "nodes_nature:salt_water_source"}, {["x"] = 3, ["y"] = 6, ["param1"] = 125, ["z"] = 12, ["name"] = "nodes_nature:salt_water_source"}, {["x"] = 3, ["y"] = 6, ["param1"] = 141, ["z"] = 13, ["name"] = "nodes_nature:salt_water_source"}, {["x"] = 3, ["y"] = 6, ["param1"] = 141, ["z"] = 14, ["name"] = "nodes_nature:salt_water_source"}, {["x"] = 3, ["y"] = 6, ["param1"] = 158, ["z"] = 15, ["name"] = "nodes_nature:salt_water_source"}, {["x"] = 3, ["meta"] = {["fields"] = {["infotext"] = "\27(T@tech)Clear Glass Window\27E\
Owned by singleplayer", ["owner"] = "singleplayer"}, ["inventory"] = {}}, ["param2"] = 2, ["y"] = 6, ["param1"] = 175, ["z"] = 16, ["name"] = "tech:window_clear"}, {["x"] = 3, ["y"] = 6, ["param1"] = 190, ["z"] = 17, ["name"] = "nodes_nature:salt_water_source"}, {["x"] = 3, ["y"] = 6, ["param1"] = 173, ["z"] = 18, ["name"] = "nodes_nature:salt_water_source"}, {["x"] = 3, ["y"] = 7, ["z"] = 0, ["name"] = "nodes_nature:sand_wet_salty"}, {["x"] = 3, ["y"] = 7, ["z"] = 1, ["name"] = "nodes_nature:sand_wet_salty"}, {["x"] = 3, ["y"] = 7, ["z"] = 2, ["name"] = "nodes_nature:sand_wet_salty"}, {["x"] = 3, ["y"] = 7, ["z"] = 3, ["name"] = "nodes_nature:sand_wet_salty"}, {["x"] = 3, ["y"] = 7, ["z"] = 4, ["name"] = "nodes_nature:sand_wet_salty"}, {["x"] = 3, ["y"] = 7, ["param1"] = 124, ["z"] = 5, ["name"] = "nodes_nature:salt_water_source"}, {["x"] = 3, ["y"] = 7, ["param1"] = 141, ["z"] = 6, ["name"] = "nodes_nature:salt_water_source"}, {["x"] = 3, ["y"] = 7, ["param1"] = 125, ["z"] = 7, ["name"] = "nodes_nature:salt_water_source"}, {["x"] = 3, ["y"] = 7, ["param1"] = 141, ["z"] = 8, ["name"] = "nodes_nature:salt_water_source"}, {["x"] = 3, ["y"] = 7, ["param1"] = 157, ["z"] = 9, ["name"] = "nodes_nature:salt_water_source"}, {["x"] = 3, ["y"] = 7, ["param1"] = 141, ["z"] = 10, ["name"] = "nodes_nature:salt_water_source"}, {["x"] = 3, ["y"] = 7, ["param1"] = 125, ["z"] = 11, ["name"] = "nodes_nature:salt_water_source"}, {["x"] = 3, ["y"] = 7, ["param1"] = 141, ["z"] = 12, ["name"] = "nodes_nature:salt_water_source"}, {["x"] = 3, ["y"] = 7, ["param1"] = 157, ["z"] = 13, ["name"] = "nodes_nature:salt_water_source"}, {["x"] = 3, ["y"] = 7, ["param1"] = 141, ["z"] = 14, ["name"] = "nodes_nature:salt_water_source"}, {["x"] = 3, ["y"] = 7, ["param1"] = 142, ["z"] = 15, ["name"] = "nodes_nature:salt_water_source"}, {["x"] = 3, ["meta"] = {["fields"] = {["infotext"] = "\27(T@tech)Clear Glass Window\27E\
Owned by singleplayer", ["owner"] = "singleplayer"}, ["inventory"] = {}}, ["y"] = 7, ["param1"] = 159, ["z"] = 16, ["name"] = "tech:window_clear"}, {["x"] = 3, ["y"] = 7, ["param1"] = 174, ["z"] = 17, ["name"] = "nodes_nature:salt_water_source"}, {["x"] = 3, ["y"] = 7, ["param1"] = 157, ["z"] = 18, ["name"] = "nodes_nature:salt_water_source"}, {["x"] = 3, ["y"] = 8, ["z"] = 0, ["name"] = "nodes_nature:sand_wet_salty"}, {["x"] = 3, ["y"] = 8, ["z"] = 1, ["name"] = "nodes_nature:sand_wet_salty"}, {["x"] = 3, ["y"] = 8, ["z"] = 2, ["name"] = "nodes_nature:sand_wet_salty"}, {["x"] = 3, ["y"] = 8, ["param1"] = 140, ["z"] = 3, ["name"] = "nodes_nature:salt_water_source"}, {["x"] = 3, ["y"] = 8, ["param1"] = 125, ["z"] = 4, ["name"] = "nodes_nature:salt_water_source"}, {["x"] = 3, ["y"] = 8, ["param1"] = 141, ["z"] = 5, ["name"] = "nodes_nature:salt_water_source"}, {["x"] = 3, ["y"] = 8, ["param1"] = 157, ["z"] = 6, ["name"] = "nodes_nature:salt_water_source"}, {["x"] = 3, ["y"] = 8, ["param1"] = 141, ["z"] = 7, ["name"] = "nodes_nature:salt_water_source"}, {["x"] = 3, ["y"] = 8, ["param1"] = 157, ["z"] = 8, ["name"] = "nodes_nature:salt_water_source"}, {["x"] = 3, ["y"] = 8, ["param1"] = 173, ["z"] = 9, ["name"] = "nodes_nature:salt_water_source"}, {["x"] = 3, ["y"] = 8, ["param1"] = 157, ["z"] = 10, ["name"] = "nodes_nature:salt_water_source"}, {["x"] = 3, ["y"] = 8, ["param1"] = 141, ["z"] = 11, ["name"] = "nodes_nature:salt_water_source"}, {["x"] = 3, ["y"] = 8, ["param1"] = 157, ["z"] = 12, ["name"] = "nodes_nature:salt_water_source"}, {["x"] = 3, ["y"] = 8, ["param1"] = 173, ["z"] = 13, ["name"] = "nodes_nature:salt_water_source"}, {["x"] = 3, ["y"] = 8, ["param1"] = 157, ["z"] = 14, ["name"] = "nodes_nature:salt_water_source"}, {["x"] = 3, ["y"] = 8, ["param1"] = 158, ["z"] = 15, ["name"] = "nodes_nature:salt_water_source"}, {["x"] = 3, ["meta"] = {["fields"] = {["infotext"] = "\27(T@tech)Clear Glass Window\27E\
Owned by singleplayer", ["owner"] = "singleplayer"}, ["inventory"] = {}}, ["y"] = 8, ["param1"] = 175, ["z"] = 16, ["name"] = "tech:window_clear"}, {["x"] = 3, ["y"] = 8, ["param1"] = 190, ["z"] = 17, ["name"] = "nodes_nature:salt_water_source"}, {["x"] = 3, ["y"] = 8, ["param1"] = 173, ["z"] = 18, ["name"] = "nodes_nature:salt_water_source"}, {["x"] = 3, ["y"] = 9, ["param1"] = 206, ["z"] = 0, ["name"] = "nodes_nature:salt_water_source"}, {["x"] = 3, ["meta"] = {["fields"] = {["owner"] = "singleplayer", ["infotext"] = "\27(T@tech)Clear Glass Window\27E\
Owned by singleplayer"}, ["inventory"] = {}}, ["y"] = 9, ["param1"] = 191, ["z"] = 1, ["name"] = "tech:window_clear"}, {["x"] = 3, ["y"] = 9, ["param1"] = 174, ["z"] = 2, ["name"] = "nodes_nature:salt_water_source"}, {["x"] = 3, ["y"] = 9, ["param1"] = 157, ["z"] = 3, ["name"] = "nodes_nature:salt_water_source"}, {["x"] = 3, ["y"] = 9, ["param1"] = 141, ["z"] = 4, ["name"] = "nodes_nature:salt_water_source"}, {["x"] = 3, ["y"] = 9, ["param1"] = 157, ["z"] = 5, ["name"] = "nodes_nature:salt_water_source"}, {["x"] = 3, ["y"] = 9, ["param1"] = 173, ["z"] = 6, ["name"] = "nodes_nature:salt_water_source"}, {["x"] = 3, ["y"] = 9, ["param1"] = 157, ["z"] = 7, ["name"] = "nodes_nature:salt_water_source"}, {["x"] = 3, ["y"] = 9, ["param1"] = 141, ["z"] = 8, ["name"] = "nodes_nature:salt_water_source"}, {["x"] = 3, ["y"] = 9, ["param1"] = 157, ["z"] = 9, ["name"] = "nodes_nature:salt_water_source"}, {["x"] = 3, ["y"] = 9, ["param1"] = 141, ["z"] = 10, ["name"] = "nodes_nature:salt_water_source"}, {["x"] = 3, ["y"] = 9, ["param1"] = 125, ["z"] = 11, ["name"] = "nodes_nature:salt_water_source"}, {["x"] = 3, ["y"] = 9, ["param1"] = 141, ["z"] = 12, ["name"] = "nodes_nature:salt_water_source"}, {["x"] = 3, ["y"] = 9, ["param1"] = 157, ["z"] = 13, ["name"] = "nodes_nature:salt_water_source"}, {["x"] = 3, ["y"] = 9, ["param1"] = 141, ["z"] = 14, ["name"] = "nodes_nature:salt_water_source"}, {["x"] = 3, ["y"] = 9, ["param1"] = 142, ["z"] = 15, ["name"] = "nodes_nature:salt_water_source"}, {["x"] = 3, ["meta"] = {["fields"] = {["infotext"] = "\27(T@tech)Clear Glass Window\27E\
Owned by singleplayer", ["owner"] = "singleplayer"}, ["inventory"] = {}}, ["y"] = 9, ["param1"] = 159, ["z"] = 16, ["name"] = "tech:window_clear"}, {["x"] = 3, ["y"] = 9, ["param1"] = 174, ["z"] = 17, ["name"] = "nodes_nature:salt_water_source"}, {["x"] = 3, ["y"] = 9, ["param1"] = 157, ["z"] = 18, ["name"] = "nodes_nature:salt_water_source"}, {["x"] = 3, ["meta"] = {["fields"] = {["infotext"] = "Sun Stone\
Owned by singleplayer", ["owner"] = "singleplayer"}, ["inventory"] = {}}, ["param2"] = 4, ["y"] = 10, ["param1"] = 223, ["z"] = 0, ["name"] = "artifacts:sun_stone"}, {["x"] = 3, ["meta"] = {["fields"] = {["owner"] = "singleplayer", ["infotext"] = "\27(T@tech)Clear Glass Window\27E\
Owned by singleplayer"}, ["inventory"] = {}}, ["y"] = 10, ["param1"] = 207, ["z"] = 1, ["name"] = "tech:window_clear"}, {["x"] = 3, ["y"] = 10, ["param1"] = 190, ["z"] = 2, ["name"] = "nodes_nature:salt_water_source"}, {["x"] = 3, ["y"] = 10, ["param1"] = 174, ["z"] = 3, ["name"] = "nodes_nature:salt_water_source"}, {["x"] = 3, ["y"] = 10, ["param1"] = 158, ["z"] = 4, ["name"] = "nodes_nature:salt_water_source"}, {["x"] = 3, ["y"] = 10, ["param1"] = 142, ["z"] = 5, ["name"] = "nodes_nature:salt_water_source"}, {["x"] = 3, ["y"] = 10, ["param1"] = 158, ["z"] = 6, ["name"] = "nodes_nature:salt_water_source"}, {["x"] = 3, ["y"] = 10, ["param1"] = 142, ["z"] = 7, ["name"] = "nodes_nature:salt_water_source"}, {["x"] = 3, ["y"] = 10, ["param1"] = 126, ["z"] = 8, ["name"] = "nodes_nature:salt_water_source"}, {["x"] = 3, ["y"] = 10, ["param1"] = 142, ["z"] = 9, ["name"] = "nodes_nature:salt_water_source"}, {["x"] = 3, ["y"] = 10, ["param1"] = 126, ["z"] = 10, ["name"] = "nodes_nature:salt_water_source"}, {["x"] = 3, ["y"] = 10, ["param1"] = 110, ["z"] = 11, ["name"] = "nodes_nature:salt_water_source"}, {["x"] = 3, ["y"] = 10, ["param1"] = 126, ["z"] = 12, ["name"] = "nodes_nature:salt_water_source"}, {["x"] = 3, ["y"] = 10, ["param1"] = 142, ["z"] = 13, ["name"] = "nodes_nature:salt_water_source"}, {["x"] = 3, ["y"] = 10, ["param1"] = 126, ["z"] = 14, ["name"] = "nodes_nature:salt_water_source"}, {["x"] = 3, ["y"] = 10, ["param1"] = 142, ["z"] = 15, ["name"] = "nodes_nature:salt_water_source"}, {["x"] = 3, ["meta"] = {["fields"] = {["infotext"] = "\27(T@tech)Clear Glass Window\27E\
Owned by singleplayer", ["owner"] = "singleplayer"}, ["inventory"] = {}}, ["y"] = 10, ["param1"] = 159, ["z"] = 16, ["name"] = "tech:window_clear"}, {["x"] = 3, ["y"] = 10, ["param1"] = 158, ["z"] = 17, ["name"] = "nodes_nature:salt_water_source"}, {["x"] = 3, ["y"] = 10, ["param1"] = 142, ["z"] = 18, ["name"] = "nodes_nature:salt_water_source"}, {["x"] = 4, ["y"] = 0, ["z"] = 0, ["name"] = "nodes_nature:limestone"}, {["x"] = 4, ["y"] = 0, ["z"] = 1, ["name"] = "nodes_nature:limestone"}, {["x"] = 4, ["y"] = 0, ["z"] = 2, ["name"] = "nodes_nature:limestone"}, {["x"] = 4, ["y"] = 0, ["z"] = 3, ["name"] = "nodes_nature:limestone"}, {["x"] = 4, ["y"] = 0, ["z"] = 4, ["name"] = "nodes_nature:limestone"}, {["x"] = 4, ["y"] = 0, ["z"] = 5, ["name"] = "nodes_nature:limestone"}, {["x"] = 4, ["y"] = 0, ["z"] = 6, ["name"] = "nodes_nature:limestone"}, {["x"] = 4, ["y"] = 0, ["z"] = 7, ["name"] = "nodes_nature:limestone"}, {["x"] = 4, ["y"] = 0, ["z"] = 8, ["name"] = "nodes_nature:limestone"}, {["x"] = 4, ["y"] = 0, ["z"] = 9, ["name"] = "nodes_nature:limestone"}, {["x"] = 4, ["y"] = 0, ["z"] = 10, ["name"] = "nodes_nature:limestone"}, {["x"] = 4, ["y"] = 0, ["z"] = 11, ["name"] = "nodes_nature:limestone"}, {["x"] = 4, ["y"] = 0, ["z"] = 12, ["name"] = "nodes_nature:limestone"}, {["x"] = 4, ["y"] = 0, ["z"] = 13, ["name"] = "nodes_nature:limestone"}, {["x"] = 4, ["y"] = 0, ["z"] = 14, ["name"] = "nodes_nature:limestone"}, {["x"] = 4, ["y"] = 0, ["z"] = 15, ["name"] = "nodes_nature:limestone"}, {["x"] = 4, ["y"] = 0, ["z"] = 16, ["name"] = "nodes_nature:sand_wet_salty"}, {["x"] = 4, ["y"] = 0, ["z"] = 17, ["name"] = "nodes_nature:sand_wet_salty"}, {["x"] = 4, ["y"] = 0, ["z"] = 18, ["name"] = "nodes_nature:sand_wet_salty"}, {["x"] = 4, ["y"] = 1, ["z"] = 0, ["name"] = "nodes_nature:limestone"}, {["x"] = 4, ["y"] = 1, ["z"] = 1, ["name"] = "nodes_nature:limestone"}, {["x"] = 4, ["y"] = 1, ["z"] = 2, ["name"] = "nodes_nature:limestone"}, {["x"] = 4, ["y"] = 1, ["z"] = 3, ["name"] = "nodes_nature:limestone"}, {["x"] = 4, ["y"] = 1, ["z"] = 4, ["name"] = "nodes_nature:limestone"}, {["x"] = 4, ["y"] = 1, ["z"] = 5, ["name"] = "nodes_nature:limestone"}, {["x"] = 4, ["y"] = 1, ["z"] = 6, ["name"] = "nodes_nature:limestone"}, {["x"] = 4, ["y"] = 1, ["z"] = 7, ["name"] = "nodes_nature:limestone"}, {["x"] = 4, ["y"] = 1, ["z"] = 8, ["name"] = "nodes_nature:limestone"}, {["x"] = 4, ["y"] = 1, ["z"] = 9, ["name"] = "nodes_nature:limestone"}, {["x"] = 4, ["y"] = 1, ["z"] = 10, ["name"] = "nodes_nature:limestone"}, {["x"] = 4, ["y"] = 1, ["z"] = 11, ["name"] = "nodes_nature:limestone"}, {["x"] = 4, ["y"] = 1, ["z"] = 12, ["name"] = "nodes_nature:sand_wet_salty"}, {["x"] = 4, ["y"] = 1, ["z"] = 13, ["name"] = "nodes_nature:sand_wet_salty"}, {["x"] = 4, ["y"] = 1, ["z"] = 14, ["name"] = "nodes_nature:sand_wet_salty"}, {["x"] = 4, ["y"] = 1, ["z"] = 15, ["name"] = "nodes_nature:sand_wet_salty"}, {["x"] = 4, ["y"] = 1, ["z"] = 16, ["name"] = "nodes_nature:sand_wet_salty"}, {["x"] = 4, ["y"] = 1, ["z"] = 17, ["name"] = "nodes_nature:sand_wet_salty"}, {["x"] = 4, ["y"] = 1, ["z"] = 18, ["name"] = "nodes_nature:sand_wet_salty"}, {["x"] = 4, ["y"] = 2, ["z"] = 0, ["name"] = "nodes_nature:limestone"}, {["x"] = 4, ["y"] = 2, ["z"] = 1, ["name"] = "nodes_nature:limestone"}, {["x"] = 4, ["y"] = 2, ["z"] = 2, ["name"] = "nodes_nature:limestone"}, {["x"] = 4, ["y"] = 2, ["z"] = 3, ["name"] = "nodes_nature:limestone"}, {["x"] = 4, ["y"] = 2, ["z"] = 4, ["name"] = "nodes_nature:limestone"}, {["x"] = 4, ["y"] = 2, ["z"] = 5, ["name"] = "nodes_nature:limestone"}, {["x"] = 4, ["y"] = 2, ["z"] = 6, ["name"] = "nodes_nature:limestone"}, {["x"] = 4, ["y"] = 2, ["z"] = 7, ["name"] = "nodes_nature:limestone"}, {["x"] = 4, ["y"] = 2, ["z"] = 8, ["name"] = "nodes_nature:limestone"}, {["x"] = 4, ["y"] = 2, ["z"] = 9, ["name"] = "nodes_nature:sand_wet_salty"}, {["x"] = 4, ["y"] = 2, ["z"] = 10, ["name"] = "nodes_nature:sand_wet_salty"}, {["x"] = 4, ["y"] = 2, ["z"] = 11, ["name"] = "nodes_nature:sand_wet_salty"}, {["x"] = 4, ["y"] = 2, ["z"] = 12, ["name"] = "nodes_nature:sand_wet_salty"}, {["x"] = 4, ["y"] = 2, ["z"] = 13, ["name"] = "nodes_nature:sand_wet_salty"}, {["x"] = 4, ["y"] = 2, ["z"] = 14, ["name"] = "nodes_nature:sand_wet_salty"}, {["x"] = 4, ["y"] = 2, ["z"] = 15, ["name"] = "nodes_nature:sand_wet_salty"}, {["x"] = 4, ["y"] = 2, ["z"] = 16, ["name"] = "nodes_nature:sand_wet_salty"}, {["x"] = 4, ["y"] = 2, ["z"] = 17, ["name"] = "nodes_nature:sand_wet_salty"}, {["x"] = 4, ["y"] = 2, ["z"] = 18, ["name"] = "nodes_nature:sand_wet_salty"}, {["x"] = 4, ["y"] = 3, ["z"] = 0, ["name"] = "nodes_nature:limestone"}, {["x"] = 4, ["y"] = 3, ["z"] = 1, ["name"] = "nodes_nature:limestone"}, {["x"] = 4, ["y"] = 3, ["z"] = 2, ["name"] = "nodes_nature:limestone"}, {["x"] = 4, ["y"] = 3, ["z"] = 3, ["name"] = "nodes_nature:limestone"}, {["x"] = 4, ["y"] = 3, ["z"] = 4, ["name"] = "nodes_nature:limestone"}, {["x"] = 4, ["y"] = 3, ["z"] = 5, ["name"] = "nodes_nature:limestone"}, {["x"] = 4, ["y"] = 3, ["z"] = 6, ["name"] = "nodes_nature:limestone"}, {["x"] = 4, ["y"] = 3, ["z"] = 7, ["name"] = "nodes_nature:sand_wet_salty"}, {["x"] = 4, ["y"] = 3, ["z"] = 8, ["name"] = "nodes_nature:sand_wet_salty"}, {["x"] = 4, ["y"] = 3, ["z"] = 9, ["name"] = "nodes_nature:sand_wet_salty"}, {["x"] = 4, ["y"] = 3, ["z"] = 10, ["name"] = "nodes_nature:sand_wet_salty"}, {["x"] = 4, ["y"] = 3, ["z"] = 11, ["name"] = "nodes_nature:sand_wet_salty"}, {["x"] = 4, ["y"] = 3, ["z"] = 12, ["name"] = "nodes_nature:sand_wet_salty"}, {["x"] = 4, ["y"] = 3, ["z"] = 13, ["name"] = "nodes_nature:sand_wet_salty"}, {["x"] = 4, ["y"] = 3, ["z"] = 14, ["name"] = "nodes_nature:sand_wet_salty"}, {["x"] = 4, ["y"] = 3, ["z"] = 15, ["name"] = "nodes_nature:sand_wet_salty"}, {["x"] = 4, ["meta"] = {["fields"] = {["infotext"] = "\27(T@tech)Clear Glass Window\27E\
Owned by singleplayer", ["owner"] = "singleplayer"}, ["inventory"] = {}}, ["param2"] = 2, ["y"] = 3, ["param1"] = 143, ["z"] = 16, ["name"] = "tech:window_clear"}, {["x"] = 4, ["y"] = 3, ["param1"] = 158, ["z"] = 17, ["name"] = "nodes_nature:salt_water_source"}, {["x"] = 4, ["y"] = 3, ["param1"] = 141, ["z"] = 18, ["name"] = "nodes_nature:salt_water_source"}, {["x"] = 4, ["y"] = 4, ["z"] = 0, ["name"] = "nodes_nature:limestone"}, {["x"] = 4, ["y"] = 4, ["z"] = 1, ["name"] = "nodes_nature:limestone"}, {["x"] = 4, ["y"] = 4, ["z"] = 2, ["name"] = "nodes_nature:limestone"}, {["x"] = 4, ["y"] = 4, ["z"] = 3, ["name"] = "nodes_nature:limestone"}, {["x"] = 4, ["y"] = 4, ["z"] = 4, ["name"] = "nodes_nature:sand_wet_salty"}, {["x"] = 4, ["y"] = 4, ["z"] = 5, ["name"] = "nodes_nature:sand_wet_salty"}, {["x"] = 4, ["y"] = 4, ["z"] = 6, ["name"] = "nodes_nature:sand_wet_salty"}, {["x"] = 4, ["y"] = 4, ["z"] = 7, ["name"] = "nodes_nature:sand_wet_salty"}, {["x"] = 4, ["y"] = 4, ["z"] = 8, ["name"] = "nodes_nature:sand_wet_salty"}, {["x"] = 4, ["y"] = 4, ["z"] = 9, ["name"] = "nodes_nature:sand_wet_salty"}, {["x"] = 4, ["y"] = 4, ["z"] = 10, ["name"] = "nodes_nature:sand_wet_salty"}, {["x"] = 4, ["y"] = 4, ["z"] = 11, ["name"] = "nodes_nature:sand_wet_salty"}, {["x"] = 4, ["y"] = 4, ["param1"] = 91, ["z"] = 12, ["name"] = "nodes_nature:salt_water_source"}, {["x"] = 4, ["y"] = 4, ["param1"] = 108, ["z"] = 13, ["name"] = "nodes_nature:salt_water_source"}, {["x"] = 4, ["y"] = 4, ["param1"] = 125, ["z"] = 14, ["name"] = "nodes_nature:salt_water_source"}, {["x"] = 4, ["y"] = 4, ["param1"] = 142, ["z"] = 15, ["name"] = "nodes_nature:salt_water_source"}, {["x"] = 4, ["meta"] = {["fields"] = {["infotext"] = "\27(T@tech)Clear Glass Window\27E\
Owned by singleplayer", ["owner"] = "singleplayer"}, ["inventory"] = {}}, ["param2"] = 2, ["y"] = 4, ["param1"] = 159, ["z"] = 16, ["name"] = "tech:window_clear"}, {["x"] = 4, ["y"] = 4, ["param1"] = 174, ["z"] = 17, ["name"] = "nodes_nature:salt_water_source"}, {["x"] = 4, ["y"] = 4, ["param1"] = 157, ["z"] = 18, ["name"] = "nodes_nature:salt_water_source"}, {["x"] = 4, ["y"] = 5, ["z"] = 0, ["name"] = "nodes_nature:limestone"}, {["x"] = 4, ["y"] = 5, ["z"] = 1, ["name"] = "nodes_nature:limestone"}, {["x"] = 4, ["y"] = 5, ["z"] = 2, ["name"] = "nodes_nature:sand_wet_salty"}, {["x"] = 4, ["y"] = 5, ["z"] = 3, ["name"] = "nodes_nature:sand_wet_salty"}, {["x"] = 4, ["y"] = 5, ["z"] = 4, ["name"] = "nodes_nature:sand_wet_salty"}, {["x"] = 4, ["y"] = 5, ["z"] = 5, ["name"] = "nodes_nature:sand_wet_salty"}, {["x"] = 4, ["y"] = 5, ["z"] = 6, ["name"] = "nodes_nature:sand_wet_salty"}, {["x"] = 4, ["y"] = 5, ["z"] = 7, ["name"] = "nodes_nature:sand_wet_salty"}, {["x"] = 4, ["y"] = 5, ["z"] = 8, ["name"] = "nodes_nature:sand_wet_salty"}, {["x"] = 4, ["y"] = 5, ["param1"] = 107, ["z"] = 9, ["name"] = "nodes_nature:salt_water_source"}, {["x"] = 4, ["y"] = 5, ["param1"] = 91, ["z"] = 10, ["name"] = "nodes_nature:salt_water_source"}, {["x"] = 4, ["y"] = 5, ["param1"] = 91, ["z"] = 11, ["name"] = "nodes_nature:salt_water_source"}, {["x"] = 4, ["y"] = 5, ["param1"] = 107, ["z"] = 12, ["name"] = "nodes_nature:salt_water_source"}, {["x"] = 4, ["y"] = 5, ["param1"] = 124, ["z"] = 13, ["name"] = "nodes_nature:salt_water_source"}, {["x"] = 4, ["y"] = 5, ["param1"] = 141, ["z"] = 14, ["name"] = "nodes_nature:salt_water_source"}, {["x"] = 4, ["y"] = 5, ["param1"] = 158, ["z"] = 15, ["name"] = "nodes_nature:salt_water_source"}, {["x"] = 4, ["meta"] = {["fields"] = {["infotext"] = "\27(T@tech)Clear Glass Window\27E\
Owned by singleplayer", ["owner"] = "singleplayer"}, ["inventory"] = {}}, ["y"] = 5, ["param1"] = 175, ["z"] = 16, ["name"] = "tech:window_clear"}, {["x"] = 4, ["y"] = 5, ["param1"] = 190, ["z"] = 17, ["name"] = "nodes_nature:salt_water_source"}, {["x"] = 4, ["y"] = 5, ["param1"] = 173, ["z"] = 18, ["name"] = "nodes_nature:salt_water_source"}, {["x"] = 4, ["y"] = 6, ["z"] = 0, ["name"] = "nodes_nature:sand_wet_salty"}, {["x"] = 4, ["y"] = 6, ["z"] = 1, ["name"] = "nodes_nature:sand_wet_salty"}, {["x"] = 4, ["y"] = 6, ["z"] = 2, ["name"] = "nodes_nature:sand_wet_salty"}, {["x"] = 4, ["y"] = 6, ["z"] = 3, ["name"] = "nodes_nature:sand_wet_salty"}, {["x"] = 4, ["y"] = 6, ["z"] = 4, ["name"] = "nodes_nature:sand_wet_salty"}, {["x"] = 4, ["y"] = 6, ["z"] = 5, ["name"] = "nodes_nature:sand_wet_salty"}, {["x"] = 4, ["y"] = 6, ["z"] = 6, ["name"] = "nodes_nature:sand_wet_salty"}, {["x"] = 4, ["y"] = 6, ["param1"] = 91, ["z"] = 7, ["name"] = "nodes_nature:salt_water_source"}, {["x"] = 4, ["y"] = 6, ["param1"] = 107, ["z"] = 8, ["name"] = "nodes_nature:salt_water_source"}, {["x"] = 4, ["y"] = 6, ["param1"] = 124, ["z"] = 9, ["name"] = "nodes_nature:salt_water_source"}, {["x"] = 4, ["y"] = 6, ["param1"] = 108, ["z"] = 10, ["name"] = "nodes_nature:salt_water_source"}, {["x"] = 4, ["y"] = 6, ["param1"] = 92, ["z"] = 11, ["name"] = "nodes_nature:salt_water_source"}, {["x"] = 4, ["y"] = 6, ["param1"] = 108, ["z"] = 12, ["name"] = "nodes_nature:salt_water_source"}, {["x"] = 4, ["y"] = 6, ["param1"] = 124, ["z"] = 13, ["name"] = "nodes_nature:salt_water_source"}, {["x"] = 4, ["y"] = 6, ["param1"] = 125, ["z"] = 14, ["name"] = "nodes_nature:salt_water_source"}, {["x"] = 4, ["y"] = 6, ["param1"] = 142, ["z"] = 15, ["name"] = "nodes_nature:salt_water_source"}, {["x"] = 4, ["meta"] = {["fields"] = {["infotext"] = "\27(T@tech)Clear Glass Window\27E\
Owned by singleplayer", ["owner"] = "singleplayer"}, ["inventory"] = {}}, ["param2"] = 2, ["y"] = 6, ["param1"] = 159, ["z"] = 16, ["name"] = "tech:window_clear"}, {["x"] = 4, ["y"] = 6, ["param1"] = 174, ["z"] = 17, ["name"] = "nodes_nature:salt_water_source"}, {["x"] = 4, ["y"] = 6, ["param1"] = 157, ["z"] = 18, ["name"] = "nodes_nature:salt_water_source"}, {["x"] = 4, ["y"] = 7, ["z"] = 0, ["name"] = "nodes_nature:sand_wet_salty"}, {["x"] = 4, ["y"] = 7, ["z"] = 1, ["name"] = "nodes_nature:sand_wet_salty"}, {["x"] = 4, ["y"] = 7, ["z"] = 2, ["name"] = "nodes_nature:sand_wet_salty"}, {["x"] = 4, ["y"] = 7, ["z"] = 3, ["name"] = "nodes_nature:sand_wet_salty"}, {["x"] = 4, ["y"] = 7, ["param1"] = 91, ["z"] = 4, ["name"] = "nodes_nature:salt_water_source"}, {["x"] = 4, ["y"] = 7, ["param1"] = 107, ["z"] = 5, ["name"] = "nodes_nature:salt_water_source"}, {["x"] = 4, ["y"] = 7, ["param1"] = 124, ["z"] = 6, ["name"] = "nodes_nature:salt_water_source"}, {["x"] = 4, ["y"] = 7, ["param1"] = 108, ["z"] = 7, ["name"] = "nodes_nature:salt_water_source"}, {["x"] = 4, ["y"] = 7, ["param1"] = 124, ["z"] = 8, ["name"] = "nodes_nature:salt_water_source"}, {["x"] = 4, ["y"] = 7, ["param1"] = 140, ["z"] = 9, ["name"] = "nodes_nature:salt_water_source"}, {["x"] = 4, ["y"] = 7, ["param1"] = 124, ["z"] = 10, ["name"] = "nodes_nature:salt_water_source"}, {["x"] = 4, ["y"] = 7, ["param1"] = 108, ["z"] = 11, ["name"] = "nodes_nature:salt_water_source"}, {["x"] = 4, ["y"] = 7, ["param1"] = 124, ["z"] = 12, ["name"] = "nodes_nature:salt_water_source"}, {["x"] = 4, ["y"] = 7, ["param1"] = 140, ["z"] = 13, ["name"] = "nodes_nature:salt_water_source"}, {["x"] = 4, ["y"] = 7, ["param1"] = 141, ["z"] = 14, ["name"] = "nodes_nature:salt_water_source"}, {["x"] = 4, ["y"] = 7, ["param1"] = 158, ["z"] = 15, ["name"] = "nodes_nature:salt_water_source"}, {["x"] = 4, ["meta"] = {["fields"] = {["infotext"] = "\27(T@tech)Clear Glass Window\27E\
Owned by singleplayer", ["owner"] = "singleplayer"}, ["inventory"] = {}}, ["y"] = 7, ["param1"] = 175, ["z"] = 16, ["name"] = "tech:window_clear"}, {["x"] = 4, ["y"] = 7, ["param1"] = 190, ["z"] = 17, ["name"] = "nodes_nature:salt_water_source"}, {["x"] = 4, ["y"] = 7, ["param1"] = 173, ["z"] = 18, ["name"] = "nodes_nature:salt_water_source"}, {["x"] = 4, ["y"] = 8, ["z"] = 0, ["name"] = "nodes_nature:sand_wet_salty"}, {["x"] = 4, ["y"] = 8, ["z"] = 1, ["name"] = "nodes_nature:sand_wet_salty"}, {["x"] = 4, ["y"] = 8, ["param1"] = 141, ["z"] = 2, ["name"] = "nodes_nature:salt_water_source"}, {["x"] = 4, ["y"] = 8, ["param1"] = 124, ["z"] = 3, ["name"] = "nodes_nature:salt_water_source"}, {["x"] = 4, ["y"] = 8, ["param1"] = 108, ["z"] = 4, ["name"] = "nodes_nature:salt_water_source"}, {["x"] = 4, ["y"] = 8, ["param1"] = 124, ["z"] = 5, ["name"] = "nodes_nature:salt_water_source"}, {["x"] = 4, ["y"] = 8, ["param1"] = 140, ["z"] = 6, ["name"] = "nodes_nature:salt_water_source"}, {["x"] = 4, ["y"] = 8, ["param1"] = 124, ["z"] = 7, ["name"] = "nodes_nature:salt_water_source"}, {["x"] = 4, ["y"] = 8, ["param1"] = 140, ["z"] = 8, ["name"] = "nodes_nature:salt_water_source"}, {["x"] = 4, ["y"] = 8, ["param1"] = 156, ["z"] = 9, ["name"] = "nodes_nature:salt_water_source"}, {["x"] = 4, ["y"] = 8, ["param1"] = 140, ["z"] = 10, ["name"] = "nodes_nature:salt_water_source"}, {["x"] = 4, ["y"] = 8, ["param1"] = 124, ["z"] = 11, ["name"] = "nodes_nature:salt_water_source"}, {["x"] = 4, ["y"] = 8, ["param1"] = 140, ["z"] = 12, ["name"] = "nodes_nature:salt_water_source"}, {["x"] = 4, ["y"] = 8, ["param1"] = 156, ["z"] = 13, ["name"] = "nodes_nature:salt_water_source"}, {["x"] = 4, ["y"] = 8, ["param1"] = 157, ["z"] = 14, ["name"] = "nodes_nature:salt_water_source"}, {["x"] = 4, ["y"] = 8, ["param1"] = 174, ["z"] = 15, ["name"] = "nodes_nature:salt_water_source"}, {["x"] = 4, ["meta"] = {["fields"] = {["infotext"] = "\27(T@tech)Clear Glass Window\27E\
Owned by singleplayer", ["owner"] = "singleplayer"}, ["inventory"] = {}}, ["y"] = 8, ["param1"] = 191, ["z"] = 16, ["name"] = "tech:window_clear"}, {["x"] = 4, ["y"] = 8, ["param1"] = 206, ["z"] = 17, ["name"] = "nodes_nature:salt_water_source"}, {["x"] = 4, ["y"] = 8, ["param1"] = 189, ["z"] = 18, ["name"] = "nodes_nature:salt_water_source"}, {["x"] = 4, ["y"] = 9, ["param1"] = 190, ["z"] = 0, ["name"] = "nodes_nature:salt_water_source"}, {["x"] = 4, ["meta"] = {["fields"] = {["owner"] = "singleplayer", ["infotext"] = "\27(T@tech)Clear Glass Window\27E\
